Workbook

Sheet General
B2: Cartera Inicial | C2: Cartera Virtual | D2: Bnf.Bruto | E2: Rent% | F2: Res.Neto
B3: =G7 -> 5000 | C3: =G11 -> 6293.3896 | D3: =C3-B3 -> 1293.3896 | E3: =D3/B3 -> 0.25867792 | F3: =N32+N31 -> 1015.6047
B5: ID Cuentas | C5: U18365480 | D5: U20750714 | E5: U21013428 | F5: U21073772 | J5: Cta-1 | K5: Cta-2 | L5: Cta-3 | M5: Cta-4 | N5: Total
B6: Alias Cuentas | C6: Cta-1 | D6: Cta-2 | E6: Cta-3 | F6: Cta-4 | G6: Total | I6: Com.Ops.Apert | J6: =Operaciones!M4 -> 32.21782 | K6: =Operaciones!M5 -> 0 | L6: =Operaciones!M6 -> 0 | M6: =Operaciones!M7 -> 0 | N6: =SUM(J6:M6) -> 32.21782
B7: Importe Inicnal | C7: =Efectivo!C5 -> 5000 | D7: =Efectivo!D5 -> 0 | E7: =Efectivo!E5 -> 0 | F7: =Efectivo!F5 -> 0 | G7: =C7+D7+E7+F7 -> 5000 | I7: Com.Ops.Cierr | J7: =Operaciones!N4 -> 29.986492 | K7: =Operaciones!N5 -> 0 | L7: =Operaciones!N6 -> 0 | M7: =Operaciones!N7 -> 0 | N7: =SUM(J7:M7) -> 29.986492
B8: Importe Actual | C8: =Efectivo!C6 -> 5000 | D8: =Efectivo!D6 -> 0 | E8: =Efectivo!E6 -> 0 | F8: =Efectivo!F6 -> 0 | G8: =C8+D8+E8+F8 -> 5000 | I8: Com.Tot.Ops | J8: =SUM(J6:J7) -> 62.204312 | K8: =SUM(K6:K7) -> 0 | L8: =SUM(L6:L7) -> 0 | M8: =SUM(M6:M7) -> 0 | N8: =SUM(N6:N7) -> 62.204312
B9: Cap. Invertido | C9: =C16 -> 6167.6736 | D9: =C17 -> 0 | E9: =C18 -> 0 | F9: =C19 -> 0 | G9: =C9+D9+E9+F9 -> 6167.6736
B10: Bnf.Neto.Ops | C10: =Operaciones!P4 -> 1111.1396 | D10: =Operaciones!P5 -> 0 | E10: =Operaciones!P6 -> 0 | F10: =Operaciones!P7 -> 0 | G10: =C10+D10+E10+F10 -> 1111.1396 | I10: Com.Tobin | J10: =Operaciones!O4 -> 53.6897 | K10: =Operaciones!O5 -> 0 | L10: =Operaciones!O6 -> 0 | M10: =Operaciones!O7 -> 0 | N10: =SUM(J10:M10) -> 53.6897
B11: Cartera Virtual | C11: =(C8+C10+J16)-J11 -> 6293.3896 | D11: =(D8+D10+K16)-K11 -> 0 | E11: =(E8+E10+L16)-L11 -> 0 | F11: =(F8+F10+M16)-M11 -> 0 | G11: =C11+D11+E11+F11 -> 6293.3896 | I11: Com.Datos | J11: =Comisiones!I8 -> 0 | N11: =SUM(J11:M11) -> 0
B12: Cash Disponible | C12: =C11-C9 -> 125.71599 | D12: =D11-D9 -> 0 | E12: =E11-E9 -> 0 | F12: =F11-F9 -> 0 | G12: =G11-G9-N11+N16 -> 307.96599 | I12: Com.Total | J12: =J8+J10+J11 -> 115.89401 | K12: =K8+K10+K11 -> 0 | L12: =L8+L10+L11 -> 0 | M12: =M8+M10+M11 -> 0 | N12: =N8+N10+N11 -> 115.89401
C14: OPERACIONES | D14: EN CURSO | I14: Dividendo.Bruto | J14: =Dividendos!C5 -> 225 | K14: =Dividendos!F5 -> 0 | L14: =Dividendos!I5 -> 0 | M14: =Dividendos!L5 -> 0 | N14: =SUM(J14:M14) -> 225
B15: Cuenta | C15: Cap.Invertido | D15: Cap.Progr | E15: Acc.Tot | F15: Op.EnCurso | G15: Op.Prog | I15: Impuestos.Div | J15: =Dividendos!D5 -> 42.75 | K15: =Dividendos!G5 -> 0 | L15: =Dividendos!J5 -> 0 | M15: =Dividendos!M5 -> 0 | N15: =SUM(J15:M15) -> 42.75
B16: Cta-1 | C16: =Operaciones!D4 -> 6167.6736 | D16: =Operaciones!C14 -> 0 | E16: =Operaciones!G4 -> 1450 | F16: =Operaciones!S4 -> 1 | G16: =Operaciones!T14 -> 0 | I16: Dividendo.Neto | J16: =J14-J15 -> 182.25 | K16: =K14-K15 -> 0 | L16: =L14-L15 -> 0 | M16: =M14-M15 -> 0 | N16: =N14-N15 -> 182.25
B17: Cta-2 | C17: =Operaciones!D5 -> 0 | D17: =Operaciones!C20 -> 0 | E17: =Operaciones!G5 -> 0 | F17: =Operaciones!S5 -> 0 | G17: =Operaciones!T20 -> 0
B18: Cta-3 | C18: =Operaciones!D6 -> 0 | D18: =Operaciones!C26 -> 0 | E18: =Operaciones!G6 -> 0 | F18: =Operaciones!S6 -> 0 | G18: =Operaciones!T26 -> 0
B19: Cta-4 | C19: =Operaciones!D7 -> 0 | D19: =Operaciones!C32 -> 0 | E19: =Operaciones!G7 -> 0 | F19: =Operaciones!S7 -> 0 | G19: =Operaciones!T32 -> 0
B20: Total | C20: =SUM(C16:C18) -> 6167.6736 | D20: =SUM(D16:D18) -> 0 | E20: =SUM(E16:E18) -> 1450 | F20: =SUM(F16:F18) -> 1 | G20: =SUM(G16:G18) -> 0
C22: OPERACIONES | D22: CERRADAS
B23: Cuenta | C23: Cap.Pos.Cerr | D23: Acc.Vendidas | E23: PrC.Prom | F23: PrV.Prom | G23: BnfxAcc.Tot | H23: Res.Tot | I23: Bnf.Neto | J23: Rent | K23: Op.Abiertas | L23: Op.Cerradas
B24: Cta-1 | C24: =Operaciones!F4 -> 21833.83 | D24: =Operaciones!H4 -> 5530 | E24: =Operaciones!I4 -> 3.968 | F24: =Operaciones!J4 -> 4.176 | G24: =Operaciones!K4 -> 1.04 | H24: =Operaciones!L4 -> 1207.36 | I24: =Operaciones!P4 -> 1111.1396 | J24: =Operaciones!Q4 -> 0.053619466 | K24: =Operaciones!R4 -> 6 | L24: =Operaciones!T4 -> 5
B25: Cta-2 | C25: =Operaciones!F5 -> 0 | D25: =Operaciones!H5 -> 0 | E25: =Operaciones!I5 -> #DIV/0! | F25: =Operaciones!J5 -> #DIV/0! | G25: =Operaciones!K5 -> 0 | H25: =Operaciones!L5 -> 0 | I25: =Operaciones!P5 -> 0 | J25: =Operaciones!Q5 -> #DIV/0! | K25: =Operaciones!R5 -> 0 | L25: =Operaciones!T5 -> 0
B26: Cta-3 | C26: =Operaciones!F6 -> 0 | D26: =Operaciones!H6 -> 0 | E26: =Operaciones!I6 -> #DIV/0! | F26: =Operaciones!J6 -> #DIV/0! | G26: =Operaciones!K6 -> 0 | H26: =Operaciones!L6 -> 0 | I26: =Operaciones!P6 -> 0 | J26: =Operaciones!Q6 -> #DIV/0! | K26: =Operaciones!R6 -> 0 | L26: =Operaciones!T6 -> 0
B27: Cta-4 | C27: =Operaciones!F7 -> 0 | D27: =Operaciones!H7 -> 0 | E27: =Operaciones!I7 -> #DIV/0! | F27: =Operaciones!J7 -> #DIV/0! | G27: =Operaciones!K7 -> 0 | H27: =Operaciones!L7 -> 0 | I27: =Operaciones!P7 -> 0 | J27: =Operaciones!Q7 -> #DIV/0! | K27: =Operaciones!R7 -> 0 | L27: =Operaciones!T7 -> 0
B28: Total | C28: =SUM(C24:C27) -> 21833.83 | D28: =SUM(D24:D27) -> 5530 | E28: =AVERAGE(E24:E27) -> #DIV/0! | F28: =AVERAGE(F24:F27) -> #DIV/0! | G28: =SUM(G24:G27) -> 1.04 | H28: =SUM(H24:H27) -> 1207.36 | I28: =SUM(I24:I27) -> 1111.1396 | J28: =I28/C28 -> 0.050890732 | K28: =SUM(K24:K26) -> 6 | L28: =SUM(L24:L26) -> 5
B30: Año | C30: Compras | D30: Ventas | E30: Res.Ops | F30: Rent | G30: Ops | H30: Res.Bruto | I30: Impuestos sobre Bnf | K30: Res.Tot | L30: Div.Neto | M30: Com.dat | N30: Res.Neto
B31: 2026 | C31: ='2026'!C3 -> 5639.259 | D31: ='2026'!D3 -> 5831.715 | E31: ='2026'!E3 -> 192.456 | F31: ='2026'!F3 -> 0.034127888 | G31: ='2026'!G3 -> 1 | H31: =E31 -> 192.456 | I31: =E31*0.25 -> 48.114 | J31: ="25%" -> 25% | K31: =E31-I31 -> 144.342 | L31: ='2026'!K3 -> 0 | M31: ='2026'!L3 -> 0 | N31: =K31+L31-M31 -> 144.342
B32: 2025 | C32: ='2025'!C3 -> 15083.431 | D32: ='2025'!D3 -> 16002.115 | E32: ='2025'!E3 -> 918.68359 | F32: ='2025'!F3 -> 0.060906804 | G32: ='2025'!G3 -> 4 | H32: =E32 -> 918.68359 | I32: =E32*0.25 -> 229.6709 | J32: ="25%" -> 25% | K32: =E32-I32 -> 689.01269 | L32: ='2025'!K3 -> 182.25 | M32: ='2025'!L3 -> 0 | N32: =K32+L32-M32 -> 871.26269

Sheet Operaciones
C2: OPERACIONES | E2: Cash disponible | F2: Cta-1 | G2: =General!C12 -> 125.71599 | H2: Cta-2 | I2: =General!D12 -> 0 | J2: Cta-3 | K2: =General!E12 -> 0 | L2: Cta-4 | M2: =General!F12 -> 0
B3: Cuenta | C3: Cap.Inv.Acc | D3: Cap.Inv.Ops | E3: Cap.Apertura | F3: Cap.Ventas | G3: Accion.Inv | H3: Acc.Liquid | I3: Pr.Com.Prom | J3: Pr.Ven.Prom | K3: BnfxAcc.Tot | L3: Result.Bruto | M3: Com.Op.Abi | N3: Com.Op.Cerr | O3: T.Tobin | P3: BnfNeto | Q3: Rent | R3: Op.Abiertas | S3: Op.enCurso | T3: Op.Cerradas
B4: Cta-1 | C4: =SUMIF(T10:T12,"Abierta",H10:H12) -> 6148 | D4: =(SUMIF(T10:T12,"abierta",H10:H12))+(SUMIF(T10:T12,"Abierta",N10:N12))+(SUMIF(T10:T12,"Abierta",P10:P12)) -> 6167.6736 | E4: =E46 -> 20722.69 | F4: =I46 -> 21833.83 | G4: =F14 -> 1450 | H4: =F46 -> 5530 | I4: =G46 -> 3.968 | J4: =J46 -> 4.176 | K4: =K46 -> 1.04 | L4: =M46 -> 1207.36 | M4: =N14+N46 -> 32.21782 | N4: =O46 -> 29.986492 | O4: =P14+P46 -> 53.6897 | P4: =Q46 -> 1111.1396 | Q4: =P4/E4 -> 0.053619466 | R4: =S14+D46 -> 6 | S4: =R4-T4 -> 1 | T4: =D46 -> 5
B5: Cta-2 | C5: =SUMIF(T16:T18,"Abierta",H16:H18) -> 0 | D5: =(SUMIF(T16:T18,"abierta",H16:H18))+(SUMIF(T16:T18,"Abierta",N16:N18))+(SUMIF(T16:T18,"Abierta",P16:P18)) -> 0 | E5: =E52 -> 0 | F5: =I52 -> 0 | G5: =F20 -> 0 | H5: =F52 -> 0 | I5: =G52 -> #DIV/0! | J5: =J52 -> #DIV/0! | K5: =K52 -> 0 | L5: =M52 -> 0 | M5: =N20+N52 -> 0 | N5: =O52 -> 0 | O5: =P20+P52 -> 0 | P5: =Q52 -> 0 | Q5: =P5/E5 -> #DIV/0! | R5: =S20+D52 -> 0 | S5: =R5-T5 -> 0 | T5: =D52 -> 0
B6: Cta-3 | C6: =SUMIF(T22:T24,"Abierta",H22:H24) -> 0 | D6: =(SUMIF(T22:T24,"abierta",H22:H24))+(SUMIF(T22:T24,"Abierta",N22:N24))+(SUMIF(T22:T24,"Abierta",P22:P24)) -> 0 | E6: =E58 -> 0 | F6: =I58 -> 0 | G6: =F26 -> 0 | H6: =F58 -> 0 | I6: =G58 -> #DIV/0! | J6: =J58 -> #DIV/0! | K6: =K58 -> 0 | L6: =M58 -> 0 | M6: =N26+N58 -> 0 | N6: =O58 -> 0 | O6: =P26+P58 -> 0 | P6: =Q58 -> 0 | Q6: =P6/E6 -> #DIV/0! | R6: =D58+S26 -> 0 | S6: =R6-T6 -> 0 | T6: =D58 -> 0
B7: Cta-4 | C7: =SUMIF(T28:T30,"Abierta",H28:H30) -> 0 | D7: =(SUMIF(T28:T30,"abierta",H28:H30))+(SUMIF(T28:T30,"Abierta",N28:N30))+(SUMIF(T28:T30,"Abierta",P28:P30)) -> 0 | E7: =E64 -> 0 | F7: =I64 -> 0 | G7: =F32 -> 0 | H7: =F64 -> 0 | I7: =G64 -> #DIV/0! | J7: =J64 -> #DIV/0! | K7: =K64 -> 0 | L7: =M64 -> 0 | M7: =M32+N64 -> 0 | N7: =O64 -> 0 | O7: =P32+P64 -> 0 | P7: =Q64 -> 0 | Q7: =P7/E7 -> #DIV/0! | R7: =D64+S32 -> 0 | S7: =R7-T7 -> 0 | T7: =D64 -> 0
B8: Total | C8: =SUM(C4:C7) -> 6148 | D8: =SUM(D4:D7) -> 6167.6736 | E8: =SUM(E4:E7) -> 20722.69 | F8: =SUM(F4:F7) -> 21833.83 | G8: =SUM(G4:G7) -> 1450 | H8: =SUM(H4:H7) -> 5530 | I8: =AVERAGE(I4:I7) -> #DIV/0! | J8: =AVERAGE(J4:J7) -> #DIV/0! | K8: =SUM(K4:K7) -> 1.04 | L8: =SUM(L4:L7) -> 1207.36 | M8: =SUM(M4:M7) -> 32.21782 | N8: =SUM(N4:N7) -> 29.986492 | O8: =SUM(O4:O7) -> 53.6897 | P8: =SUM(P4:P7) -> 1111.1396 | Q8: =P8/F8 -> 0.050890732 | R8: =SUM(R4:R7) -> 6 | S8: =SUM(S4:S7) -> 1 | T8: =SUM(T4:T7) -> 5
B9: Cuenta | C9: Valor | D9: Nº Op. | E9: Apertura | F9: Acciones | G9: Pr.Compra | H9: Compra € | I9: Cierre | J9: Pr.Venta | K9: BnfxAcc | L9: Venta € | M9: Res.Venta | N9: Com.Op.Ap | O9: Com.Op.Cierr | P9: T.Tobin | Q9: BnfNeto | R9: Rent | S9: Mes.Cierre | T9: Estado
B10: Cta-1 | C10: IAG - IAG | D10: 1 | E10: 46119 | F10: 1450 | G10: 4.24 | H10: =G10*F10 -> 6148 | I10: x/1 | J10: 4.5 | K10: =J10-G10 -> 0.26 | L10: =F10*J10 -> 6525 | M10: =F10*K10 -> 377 | N10: {=_xlfn.IFS(E10="",0,H10<4166.67,5,H10>4166.67,H10*0.12%)} -> 7.3776 | O10: {=_xlfn.IFS(I10="",0,L10<4166.67,5,L10>4166.67,L10*0.12%)} -> 7.83 | P10: =H10*0.002 -> 12.296 | Q10: =M10-(N10+O10+P10) -> 349.4964 | R10: =Q10/H10 -> 0.05684717 | T10: Abierta
C13: Cap.Program | D13: Operaciones | E13: Cap.Apertura | F13: Acc.Tot | G13: PrC.Prom | H13: Compra.Tot | I13: Cap.Venta | J13: PrV.Prom | K13: BnfxAcc.Tot | L13: Venta.Tot | M13: Res.Tot | N13: Com.Ap.Tot | O13: Com.Cierr.Tot | P13: T.Tobin | Q13: Bnf.Tot | R13: Rent | S13: Op.Abiertas | T13: Op.Program
C14: =SUMIF(T10:T12,"Programada",H10:H12)+(SUMIF(T10:T12,"Programada",N10:N12)) -> 0 | D14: =COUNTA(E10:E12) -> 1 | E14: =H14+N14 -> 6155.3776 | F14: =SUMIF(T10:T12,"Abierta",F10:F12) -> 1450 | G14: =AVERAGEIF(T10:T12,"Abierta",G10:G12) -> 4.24 | H14: =SUM(H10:H12) -> 6148 | I14: =L14-(O14+P14) -> 6504.874 | J14: =AVERAGEIF(T10:T12,"Abierta",J10:J12) -> 4.5 | K14: =SUM(K10:K12) -> 0.26 | L14: =SUM(L10:L12) -> 6525 | M14: =SUM(M10:M12) -> 377 | N14: =SUMIF(T10:T12,"Abierta",N10:N12) -> 7.3776 | O14: =SUM(O10:O12) -> 7.83 | P14: =SUMIF(T10:T12,"Abierta",P10:P12) -> 12.296 | Q14: =SUM(Q10:Q12) -> 349.4964 | R14: =Q14/H14 -> 0.05684717 | S14: =COUNTIF(T10:T12,"Abierta") -> 1 | T14: =COUNTIF(T10:T12,"Programada") -> 0
B15: Cuenta | C15: Valor | D15: Nº Op. | E15: Apertura | F15: Acciones | G15: Pr.Compra | H15: Compra € | I15: Cierre | J15: Pr.Venta | K15: BnfxAcc | L15: Venta € | M15: Res.Venta | N15: Com.Op.Ap | O15: Com.Op.Cierr | P15: T.Tobin | Q15: BnfNeto | R15: Rent | S15: Mes.Cierre | T15: Estado
B16: Cta-2
C19: Cap.Program | D19: Operaciones | E19: Cap.Apertura | F19: Acc.Tot | G19: PrC.Prom | H19: Compra.Tot | I19: Cap.Venta | J19: PrV.Prom | K19: BnfxAcc.Tot | L19: Venta.Tot | M19: Res.Tot | N19: Com.Ap.Tot | O19: Com.Cierr.Tot | P19: T.Tobin | Q19: Bnf.Tot | R19: Rent | S19: Op.Abiertas | T19: Op.Program
C20: =SUMIF(T16:T18,"Programada",H16:H18)+(SUMIF(T16:T18,"Programada",N16:N18)) -> 0 | D20: =COUNTA(E16:E18) -> 0 | E20: =H20+N20 -> 0 | F20: =SUMIF(T16:T18,"Abierta",F16:F18) -> 0 | G20: =AVERAGEIF(T16:T18,"Abierta",G16:G18) -> #DIV/0! | H20: =SUM(F16:F18) -> 0 | I20: =L20-(O20+P20) -> 0 | J20: =AVERAGEIF(T16:T18,"Abierta",J16:J18) -> #DIV/0! | K20: =SUM(K16:K18) -> 0 | L20: =SUM(L16:L18) -> 0 | M20: =SUM(M16:M18) -> 0 | N20: =SUMIF(T16:T18,"Abierta",N16:N18) -> 0 | O20: =SUM(O16:O18) -> 0 | P20: =SUMIF(T16:T18,"Abierta",P16:P18) -> 0 | Q20: =SUM(Q16:Q18) -> 0 | R20: =Q20/H20 -> #DIV/0! | S20: =COUNTIF(T16:T18,"Abierta") -> 0 | T20: =COUNTIF(T16:T18,"Programada") -> 0
B21: Cuenta | C21: Valor | D21: Nº Op. | E21: Apertura | F21: Acciones | G21: Pr.Compra | H21: Compra € | I21: Cierre | J21: Pr.Venta | K21: BnfxAcc | L21: Venta € | M21: Res.Venta | N21: Com.Op.Ap | O21: Com.Op.Cierr | P21: T.Tobin | Q21: BnfNeto | R21: Rent | S21: Mes.Cierre | T21: Estado
B22: Cta-3
C25: Cap.Program | D25: Operaciones | E25: Cap.Apertura | F25: Acc.Tot | G25: PrC.Prom | H25: Compra.Tot | I25: Cap.Venta | J25: PrV.Prom | K25: BnfxAcc.Tot | L25: Venta.Tot | M25: Res.Tot | N25: Com.Ap.Tot | O25: Com.Cierr.Tot | P25: T.Tobin | Q25: Bnf.Tot | R25: Rent | S25: Op.Abiertas | T25: Op.Program
C26: =SUMIF(T22:T24,"Programada",H22:H24)+(SUMIF(T22:T24,"Programada",N22:N24)) -> 0 | D26: =COUNTA(E22:E24) -> 0 | E26: =H26+N26 -> 0 | F26: =SUMIF(T16:T18,"Abierta",F16:F18) -> 0 | G26: =AVERAGEIF(T22:T24,"Abierta",G22:G24) -> #DIV/0! | H26: =SUM(F22:F24) -> 0 | I26: =L26-(O26+P26) -> 0 | J26: =AVERAGEIF(T22:T24,"Abierta",J22:J24) -> #DIV/0! | K26: =SUM(K22:K24) -> 0 | L26: =SUM(L22:L24) -> 0 | M26: =SUM(M22:M24) -> 0 | N26: =SUMIF(T22:T24,"Abierta",N22:N24) -> 0 | O26: =SUM(O22:O24) -> 0 | P26: =SUMIF(T22:T24,"Abierta",P22:P24) -> 0 | Q26: =SUM(Q22:Q24) -> 0 | R26: =Q26/H26 -> #DIV/0! | S26: =COUNTIF(T22:T24,"Abierta") -> 0 | T26: =COUNTIF(T22:T24,"Programada") -> 0
B27: Cuenta | C27: Valor | D27: Nº Op. | E27: Apertura | F27: Acciones | G27: Pr.Compra | H27: Compra € | I27: Cierre | J27: Pr.Venta | K27: BnfxAcc | L27: Venta € | M27: Res.Venta | N27: Com.Op.Ap | O27: Com.Op.Cierr | P27: T.Tobin | Q27: BnfNeto | R27: Rent | S27: Mes.Cierre | T27: Estado
B28: Cta-4
C31: Cap.Program | D31: Operaciones | E31: Cap.Apertura | F31: Acc.Tot | G31: PrC.Prom | H31: Compra.Tot | I31: Cap.Venta | J31: PrV.Prom | K31: BnfxAcc.Tot | L31: Venta.Tot | M31: Res.Tot | N31: Com.Ap.Tot | O31: Com.Cierr.Tot | P31: T.Tobin | Q31: Bnf.Tot | R31: Rent | S31: Op.Abiertas | T31: Op.Program
C32: =SUMIF(T28:T30,"Programada",H28:H30)+(SUMIF(T28:T30,"Programada",N28:N30)) -> 0 | D32: =COUNTA(E28:E30) -> 0 | E32: =H32+N32 -> 0 | F32: =SUMIF(T16:T18,"Abierta",F16:F18) -> 0 | G32: =AVERAGEIF(T28:T30,"Abierta",G28:G30) -> #DIV/0! | H32: =SUM(F28:F30) -> 0 | I32: =L32-(O32+P32) -> 0 | J32: =AVERAGEIF(T28:T30,"Abierta",J28:J30) -> #DIV/0! | K32: =SUM(K28:K30) -> 0 | L32: =SUM(L28:L30) -> 0 | M32: =SUM(M28:M30) -> 0 | N32: =SUMIF(T28:T30,"Abierta",N28:N30) -> 0 | O32: =SUM(O28:O30) -> 0 | P32: =SUMIF(T28:T30,"Abierta",P28:P30) -> 0 | Q32: =SUM(Q26:Q30) -> 0 | R32: =Q32/H32 -> #DIV/0! | S32: =COUNTIF(T28:T30,"Abierta") -> 0 | T32: =COUNTIF(T28:T30,"Programada") -> 0
C33: Plantilla Operación
H34: =G34*F34 -> 0 | K34: =J34-G34 -> 0 | L34: =F34*J34 -> 0 | M34: =F34*K34 -> 0 | N34: {=_xlfn.IFS(E34="",0,H34<4166.67,5,H34>4166.67,H34*0.12%)} -> 0 | O34: {=_xlfn.IFS(I34="",0,L34<4166.67,5,L34>4166.67,L34*0.12%)} -> 0 | P34: =H34*0.002 -> 0 | Q34: =M34-(N34+O34+P34) -> 0 | R34: =Q34/H34 -> #DIV/0!
C36: OPERACIONES | D36: CERRADAS
B37: Cuenta | C37: Valor | D37: Nº Op. | E37: Apertura | F37: Acciones | G37: Pr.Compra | H37: Compra € | I37: Cierre | J37: Pr.Venta | K37: BnfxAcc | L37: Venta € | M37: Res.Venta | N37: Com.Op.Ap | O37: Com.Op.Cierr | P37: T.Tobin | Q37: BnfNeto | R37: Rent | S37: Mes.Cierre | T37: Estado
B38: Cta-1
C39: TEF - Telefónica | D39: 1 | E39: 45965 | F39: 1500 | G39: 3.755 | H39: =G39*F39 -> 5632.5 | I39: 46119 | J39: 3.9 | K39: =J39-G39 -> 0.145 | L39: =F39*J39 -> 5850 | M39: =F39*K39 -> 217.5 | N39: {=_xlfn.IFS(E39="",0,H39<4166.67,5,H39>4166.67,H39*0.12%)} -> 6.759 | O39: {=_xlfn.IFS(I39="",0,L39<4166.67,5,L39>4166.67,L39*0.12%)} -> 7.02 | P39: =H39*0.002 -> 11.265 | Q39: =M39-(N39+O39+P39) -> 192.456 | R39: =Q39/H39 -> 0.034168842 | S39: Abr | T39: Cerrada
C40: ↓↓↓ 2025 ↓↓↓
C41: SAB1 - Sabadell | D41: 2 | E41: 45947 | F41: 1700 | G41: 2.97 | H41: =G41*F41 -> 5049 | I41: 45965 | J41: 3.3 | K41: =J41-G41 -> 0.33 | L41: =F41*J41 -> 5610 | M41: =F41*K41 -> 561 | N41: {=_xlfn.IFS(E41="",0,H41<4166.67,5,H41>4166.67,H41*0.12%)} -> 6.0588 | O41: {=_xlfn.IFS(I41="",0,L41<4166.67,5,L41>4166.67,L41*0.12%)} -> 6.732 | P41: =H41*0.002 -> 10.098 | Q41: =M41-(N41+O41+P41) -> 538.1112 | R41: =Q41/H41 -> 0.10657778 | S41: Nov | T41: Cerrada
C42: SAB1 - Sabadell | D42: 1.2 | E42: 45917 | F42: 600 | G42: 3.16 | H42: =G42*F42 -> 1896 | I42: 45919 | J42: 3.283 | K42: =J42-G42 -> 0.123 | L42: =F42*J42 -> 1969.8 | M42: =F42*K42 -> 73.8 | O42: {=_xlfn.IFS(I42="",0,L42<4166.67,5,L42>4166.67,L42*0.12%)} -> 5 | Q42: =M42-(N42+O42+P42) -> 68.8 | R42: =Q42/H42 -> 0.03628692 | S42: Sep | T42: Cerrada
C43: SAB1 - Sabadell | D43: 1.1 | E43: 45917 | F43: 1000 | G43: 3.16 | H43: =G43*F43 -> 3160 | I43: 45919 | J43: 3.28 | K43: =J43-G43 -> 0.12 | L43: =F43*J43 -> 3280 | M43: =F43*K43 -> 120 | N43: 6.07 | O43: {=_xlfn.IFS(I43="",0,L43<4166.67,5,L43>4166.67,L43*0.12%)} -> 5 | P43: 10.11 | Q43: =M43-(N43+O43+P43) -> 98.82 | R43: =Q43/H43 -> 0.031272152 | S43: Sep | T43: Cerrada
C44: SAN - Santander | D44: 1 | E44: 45825 | F44: 730 | G44: 6.795 | H44: =G44*F44 -> 4960.35 | I44: 45832 | J44: 7.117 | K44: =J44-G44 -> 0.322 | L44: =F44*J44 -> 5195.41 | M44: =F44*K44 -> 235.06 | N44: {=_xlfn.IFS(E44="",0,H44<4166.67,5,H44>4166.67,H44*0.12%)} -> 5.95242 | O44: {=_xlfn.IFS(I44="",0,L44<4166.67,5,L44>4166.67,L44*0.12%)} -> 6.234492 | P44: =H44*0.002 -> 9.9207 | Q44: =M44-(N44+O44+P44) -> 212.95239 | R44: =Q44/H44 -> 0.04293092 | S44: Jun | T44: Cerrada
D45: Operaciones | E45: Cap.Apertura | F45: Acc.Tot | G45: PrC.Prom | H45: Compra.Tot | I45: Cap.Venta | J45: PrV.Prom | K45: BnfxAcc.Tot | L45: Venta.Tot | M45: Res.Tot | N45: Com.Ap.Tot | O45: Com.Cierr.Tot | P45: T.Tobin | Q45: Bnf.Tot | R45: Rent | S45: Res.Tot | T45: Res-Tobin
D46: =COUNTA(E38:E44) -> 5 | E46: =H46+N46 -> 20722.69 | F46: =SUM(F38:F44) -> 5530 | G46: =AVERAGE(G38:G44) -> 3.968 | H46: =SUM(H38:H44) -> 20697.85 | I46: =L46-(O46+P46) -> 21833.83 | J46: =AVERAGE(J38:J44) -> 4.176 | K46: =SUM(K38:K44) -> 1.04 | L46: =SUM(L38:L44) -> 21905.21 | M46: =SUM(M38:M44) -> 1207.36 | N46: =SUM(N38:N44) -> 24.84022 | O46: =SUM(O38:O44) -> 29.986492 | P46: =SUM(P38:P44) -> 41.3937 | Q46: =SUM(Q38:Q44) -> 1111.1396 | R46: =Q46/H46 -> 0.053683817 | S46: =SUM(P38:Q44) -> 1152.5333 | T46: =I46-E46 -> 1111.1396
B47: Cuenta | C47: Valor | D47: Nº Op. | E47: Apertura | F47: Acciones | G47: Pr.Compra | H47: Compra € | I47: Cierre | J47: Pr.Venta | K47: BnfxAcc | L47: Venta € | M47: Res.Venta | N47: Com.Op.Ap | O47: Com.Op.Cierr | P47: T.Tobin | Q47: BnfNeto | R47: Rent | S47: Mes.Cierre | T47: Estado
B48: Cta-2
C50: ↓↓↓ 2025 ↓↓↓
D51: Operaciones | E51: Cap.Apertura | F51: Acc.Tot | G51: PrC.Prom | H51: Compra.Tot | I51: Cap.Venta | J51: PrV.Prom | K51: BnfxAcc.Tot | L51: Venta.Tot | M51: Res.Tot | N51: Com.Ap.Tot | O51: Com.Cierr.Tot | P51: T.Tobin | Q51: Bnf.Tot | R51: Rent | S51: Res.Tot | T51: Res-Tobin
...

Sheet Op.por Valor
C2: SAN-Santander
C3: Nº Op. | D3: Apertura | E3: Acciones | F3: Pr.Compra | G3: Compra € | H3: Cierre | I3: Pr.Venta | J3: BnfxAcc | K3: Venta € | L3: Res.Venta | M3: Com.Op.Ap | N3: Com.Op.Cierr | O3: T.Tobin | P3: BnfNeto | Q3: Rent | R3: Mes.Cierre | S3: Año
B4: Cta-1 | C4: 1 | D4: 45825 | E4: 730 | F4: 6.795 | G4: =F4*E4 -> 4960.35 | H4: 24.6 | I4: 7.117 | J4: =I4-F4 -> 0.322 | K4: =E4*I4 -> 5195.41 | L4: =E4*J4 -> 235.06 | M4: {=_xlfn.IFS(D4="",0,G4<4166.67,5,G4>4166.67,G4*0.12%)} -> 5.95242 | N4: {=_xlfn.IFS(H4="",0,K4<4166.67,5,K4>4166.67,K4*0.12%)} -> 6.234492 | O4: =G4*0.002 -> 9.9207 | P4: =L4-(M4+N4+O4) -> 212.95239 | Q4: =P4/G4 -> 0.04293092 | R4: Jun | S4: 2025
C6: Operaciones | D6: Cap.Apertura | E6: Acc.Tot | F6: PrC.Prom | G6: Compra.Tot | H6: Cap.Venta | I6: PrV.Prom | J6: BnfxAcc.Tot | K6: Venta.Tot | L6: Res.Tot | M6: Com.Ap.Tot | N6: Com.Cierr.Tot | O6: T.Tobin | P6: Bnf.Tot | Q6: Rent | R6: Res.Tot | S6: Res-Tobin
C7: =COUNTA(D4:D5) -> 1 | D7: =G7+M7 -> 4966.3024 | E7: =SUM(E4:E5) -> 730 | F7: =AVERAGE(F4:F5) -> 6.795 | G7: =SUM(G4:G5) -> 4960.35 | H7: =K7-(N7+O7) -> 5179.2548 | I7: =AVERAGE(I4:I5) -> 7.117 | J7: =SUM(J4:J5) -> 0.322 | K7: =SUM(K4:K5) -> 5195.41 | L7: =SUM(L4:L5) -> 235.06 | M7: =SUM(M4:M5) -> 5.95242 | N7: =SUM(N4:N5) -> 6.234492 | O7: =SUM(O4:O5) -> 9.9207 | P7: =SUM(P4:P5) -> 212.95239 | Q7: =P7/G7 -> 0.04293092 | R7: =SUM(O4:P5) -> 222.87309 | S7: =H7-D7 -> 212.95239
C9: SAB-Sabadell
C10: Nº Op. | D10: Apertura | E10: Acciones | F10: Pr.Compra | G10: Compra € | H10: Cierre | I10: Pr.Venta | J10: BnfxAcc | K10: Venta € | L10: Res.Venta | M10: Com.Op.Ap | N10: Com.Op.Cierr | O10: T.Tobin | P10: BnfNeto | Q10: Rent | R10: Mes.Cierre | S10: Año
B11: Cta-1 | C11: 1.1 | D11: 45917 | E11: 1000 | F11: 3.16 | G11: =F11*E11 -> 3160 | H11: 45919 | I11: 3.28 | J11: =I11-F11 -> 0.12 | K11: =E11*I11 -> 3280 | L11: =E11*J11 -> 120 | M11: 6.07 | N11: {=_xlfn.IFS(H11="",0,K11<4166.67,5,K11>4166.67,K11*0.12%)} -> 5 | O11: 10.11 | P11: =L11-(M11+N11+O11) -> 98.82 | Q11: =P11/G11 -> 0.031272152 | R11: Sep | S11: 2025
B12: Cta-1 | C12: 1.2 | D12: 45917 | E12: 600 | F12: 3.16 | G12: =F12*E12 -> 1896 | H12: 45919 | I12: 3.283 | J12: =I12-F12 -> 0.123 | K12: =E12*I12 -> 1969.8 | L12: =E12*J12 -> 73.8 | N12: {=_xlfn.IFS(H12="",0,K12<4166.67,5,K12>4166.67,K12*0.12%)} -> 5 | P12: =L12-(M12+N12+O12) -> 68.8 | Q12: =P12/G12 -> 0.03628692 | R12: Sep | S12: 2025
B13: Cta-1 | C13: 2 | D13: 45947 | E13: 1700 | F13: 2.97 | G13: =F13*E13 -> 5049 | H13: 45965 | I13: 3.3 | J13: =I13-F13 -> 0.33 | K13: =E13*I13 -> 5610 | L13: =E13*J13 -> 561 | M13: {=_xlfn.IFS(D13="",0,G13<4166.67,5,G13>4166.67,G13*0.12%)} -> 6.0588 | N13: {=_xlfn.IFS(H13="",0,K13<4166.67,5,K13>4166.67,K13*0.12%)} -> 6.732 | O13: =G13*0.002 -> 10.098 | P13: =L13-(M13+N13+O13) -> 538.1112 | Q13: =P13/G13 -> 0.10657778 | R13: Nov | S13: 2025
C15: Operaciones | D15: Cap.Apertura | E15: Acc.Tot | F15: PrC.Prom | G15: Compra.Tot | H15: Cap.Venta | I15: PrV.Prom | J15: BnfxAcc.Tot | K15: Venta.Tot | L15: Res.Tot | M15: Com.Ap.Tot | N15: Com.Cierr.Tot | O15: T.Tobin | P15: Bnf.Tot | Q15: Rent | R15: Res.Tot | S15: Res-Tobin
C16: =COUNTA(D11:D14) -> 3 | D16: =G16+M16 -> 10117.129 | E16: =SUM(E11:E14) -> 3300 | F16: =AVERAGE(F11:F14) -> 3.0966667 | G16: =SUM(G11:G14) -> 10105 | H16: =K16-(N16+O16) -> 10822.86 | I16: =AVERAGE(I11:I14) -> 3.2876667 | J16: =SUM(J11:J14) -> 0.573 | K16: =SUM(K11:K14) -> 10859.8 | L16: =SUM(L11:L14) -> 754.8 | M16: =SUM(M11:M14) -> 12.1288 | N16: =SUM(N11:N14) -> 16.732 | O16: =SUM(O11:O14) -> 20.208 | P16: =SUM(P11:P14) -> 705.7312 | Q16: =P16/G16 -> 0.069839802 | R16: =SUM(O11:P14) -> 725.9392 | S16: =H16-D16 -> 705.7312
C18: TEF-Telefónica
C19: Nº Op. | D19: Apertura | E19: Acciones | F19: Pr.Compra | G19: Compra € | H19: Cierre | I19: Pr.Venta | J19: BnfxAcc | K19: Venta € | L19: Res.Venta | M19: Com.Op.Ap | N19: Com.Op.Cierr | O19: T.Tobin | P19: BnfNeto | Q19: Rent | R19: Mes.Cierre | S19: Año
B20: Cta-1 | C20: 1 | D20: 45965 | E20: 1500 | F20: 3.755 | G20: =F20*E20 -> 5632.5 | H20: 46119 | I20: 3.9 | J20: =I20-F20 -> 0.145 | K20: =E20*I20 -> 5850 | L20: =E20*J20 -> 217.5 | M20: {=_xlfn.IFS(D20="",0,G20<4166.67,5,G20>4166.67,G20*0.12%)} -> 6.759 | N20: {=_xlfn.IFS(H20="",0,K20<4166.67,5,K20>4166.67,K20*0.12%)} -> 7.02 | O20: =G20*0.002 -> 11.265 | P20: =L20-(M20+N20+O20) -> 192.456 | Q20: =P20/G20 -> 0.034168842 | R20: Abr | S20: 2026
C22: Operaciones | D22: Cap.Apertura | E22: Acc.Tot | F22: PrC.Prom | G22: Compra.Tot | H22: Cap.Venta | I22: PrV.Prom | J22: BnfxAcc.Tot | K22: Venta.Tot | L22: Res.Tot | M22: Com.Ap.Tot | N22: Com.Cierr.Tot | O22: T.Tobin | P22: Bnf.Tot | Q22: Rent | R22: Res.Tot | S22: Res-Tobin
C23: =COUNTA(D20:D21) -> 1 | D23: =G23+M23 -> 5639.259 | E23: =SUM(E20:E21) -> 1500 | F23: =AVERAGE(F20:F21) -> 3.755 | G23: =SUM(G20:G21) -> 5632.5 | H23: =K23-(N23+O23) -> 5831.715 | I23: =AVERAGE(I20:I21) -> 3.9 | J23: =SUM(J20:J21) -> 0.145 | K23: =SUM(K20:K21) -> 5850 | L23: =SUM(L20:L21) -> 217.5 | M23: =SUM(M20:M21) -> 6.759 | N23: =SUM(N20:N21) -> 7.02 | O23: =SUM(O20:O21) -> 11.265 | P23: =SUM(P20:P21) -> 192.456 | Q23: =P23/G23 -> 0.034168842 | R23: =SUM(O20:P21) -> 203.721 | S23: =H23-D23 -> 192.456

Sheet Efectivo
C3: Cta-1 | D3: Cta-2 | E3: Cta-3 Fut | F3: Cta-4
C4: U18365480 | D4: U20750714 | E4: U21013428 | F4: U21073772 | G4: Total
B5: Saldo Inicial | C5: =G27+G13 -> 5000 | D5: =H27+H13 -> 0 | E5: =I27+I13 -> 0 | F5: =J27+J13 -> 0 | G5: =SUM(C5:F5) -> 5000
B6: Saldo Actual | C6: =G27+G30+G33+G13+G17+G21 -> 5000 | D6: =H27+H30+H33+H13+H17+H21 -> 0 | E6: =I27+I30+I33+I13+I17+I21 -> 0 | F6: =J27+J30+J33+I13+I17+I21 -> 0 | G6: =SUM(C6:F6) -> 5000
B7: Saldo Disponible | C7: =General!C12 -> 125.71599 | D7: =General!D12 -> 0 | E7: =General!E12 -> 0 | F7: =General!F12 -> 0 | G7: =SUM(C7:F7) -> 125.71599
B9: Transferencias 2026
B10: Depósitos | C10: Fecha | D10: Banco | E10: Cta Destino | F10: Importe | G10: Cta-1 | H10: Cta-2 | I10: Cta-3 | J10: Cta-4
G12: =_xlfn.IFS($E12<>"Cta-1",0,$E12="Cta-1",F12) -> 0 | H12: =_xlfn.IFS($E12<>"Cta-2",0,$E12="Cta-2",F12) -> 0 | I12: =_xlfn.IFS($E12<>"Cta-3",0,$E12="Cta-3",F12) -> 0 | J12: =_xlfn.IFS($E12<>"Cta-4",0,$E12="Cta-4",F12) -> 0
E13: Total | F13: =SUM(F11:F12) -> 0 | G13: =SUM(G11:G12) -> 0 | H13: =SUM(H11:H12) -> 0 | I13: =SUM(I11:I12) -> 0 | J13: =SUM(J11:J12) -> 0
B14: Retiradas | C14: Fecha | D14: Cta Origen | E14: Banco | F14: Importe | G14: Cta-1 | H14: Cta-2 | I14: Cta-3 | J14: Cta-4
E17: Total | F17: =SUM(F15:F16) -> 0 | G17: =SUM(G15:G16) -> 0 | H17: =SUM(H15:H16) -> 0 | I17: =SUM(I15:I16) -> 0 | J17: =SUM(J15:J16) -> 0
B18: Internas | C18: Fecha | D18: Cta Origen | E18: Cta Destino | F18: Importe | G18: Cta-1 | H18: Cta-2 | I18: Cta-3 | J18: Cta-4
I19: =_xlfn.IFS($D19=$E19,0,$D19="Cta-3",F19*(-1),$E19="Cta-3",F19,$D19<>"Cta-3",0,$F19<>"Cta-3",0) -> 0 | J19: =_xlfn.IFS($D19=$E19,0,$D19="Cta-4",F19*(-1),$E19="Cta-4",F19,$D19<>"Cta-4",0,$F19<>"Cta-4",0) -> 0
F21: Total | G21: =SUM(G19:G20) -> 0 | H21: =SUM(H19:H20) -> 0 | I21: =SUM(I19:I20) -> 0 | J21: =SUM(J19:J20) -> 0
B23: Transferencias 2025
B24: Depósitos | C24: Fecha | D24: Banco | E24: Cta Destino | F24: Importe | G24: Cta-1 | H24: Cta-2 | I24: Cta-3 | J24: Cta-4
C25: 45758 | D25: Santander | E25: Cta-1 | F25: 5000 | G25: =_xlfn.IFS($E25<>"Cta-1",0,$E25="Cta-1",F25) -> 5000 | H25: =_xlfn.IFS($E25<>"Cta-2",0,$E25="Cta-2",F25) -> 0 | I25: =_xlfn.IFS($E25<>"Cta-3",0,$E25="Cta-3",F25) -> 0 | J25: =_xlfn.IFS($E25<>"Cta-4",0,$E25="Cta-4",F25) -> 0
G26: =_xlfn.IFS($E26<>"Cta-1",0,$E26="Cta-1",F26) -> 0 | H26: =_xlfn.IFS($E26<>"Cta-2",0,$E26="Cta-2",F26) -> 0 | I26: =_xlfn.IFS($E26<>"Cta-3",0,$E26="Cta-3",F26) -> 0 | J26: =_xlfn.IFS($E26<>"Cta-4",0,$E26="Cta-4",F26) -> 0
E27: Total | F27: =SUM(F25:F26) -> 5000 | G27: =SUM(G25:G26) -> 5000 | H27: =SUM(H25:H26) -> 0 | I27: =SUM(I25:I26) -> 0 | J27: =SUM(J25:J26) -> 0
B28: Retiradas | C28: Fecha | D28: Cta Origen | E28: Banco | F28: Importe | G28: Cta-1 | H28: Cta-2 | I28: Cta-3 | J28: Cta-4
E30: Total | F30: =SUM(F29:F29) -> 0 | G30: =SUM(G29:G29) -> 0 | H30: =SUM(H29:H29) -> 0 | I30: =SUM(I29:I29) -> 0 | J30: =SUM(J29:J29) -> 0
B31: Internas | C31: Fecha | D31: Cta Origen | E31: Cta Destino | F31: Importe | G31: Cta-1 | H31: Cta-2 | I31: Cta-3 | J31: Cta-4
F33: Total | G33: =SUM(G32:G32) -> 0 | H33: =SUM(H32:H32) -> 0 | I33: =SUM(I32:I32) -> 0 | J33: =SUM(J32:J32) -> 0

Sheet Comisiones
B2: Comisiones por Operativa
B3: Cuenta | C3: Apert.Op | D3: Cierre.Op | E3: Total | F3: T.Tobin | G3: Total
B4: Cta-1 | C4: =Operaciones!M4 -> 32.21782 | D4: =Operaciones!N4 -> 29.986492 | E4: =C4+D4 -> 62.204312 | F4: =Operaciones!O4 -> 53.6897 | G4: =E4+F4 -> 115.89401 | H4: Com.Datos.Tiempo.Real
B5: Cta-2 | C5: =Operaciones!M5 -> 0 | D5: =Operaciones!N5 -> 0 | E5: =C5+D5 -> 0 | F5: =Operaciones!O5 -> 0 | G5: =E5+F5 -> 0 | H5: Datos.TR | I5: Total
B6: Cta-3 | C6: =Operaciones!M6 -> 0 | D6: =Operaciones!N6 -> 0 | E6: =C6+D6 -> 0 | F6: =Operaciones!O6 -> 0 | G6: =E6+F6 -> 0 | H6: Datos | I6: =U13+U20 -> 0
B7: Cta-4 | C7: =Operaciones!M7 -> 0 | D7: =Operaciones!N7 -> 0 | E7: =C7+D7 -> 0 | F7: =Operaciones!O7 -> 0 | G7: =E7+F7 -> 0 | H7: Imp.Ventas | I7: =U14+U21 -> 0
B8: Total | C8: =SUM(C4:C7) -> 32.21782 | D8: =SUM(D4:D7) -> 29.986492 | E8: =SUM(E4:E7) -> 62.204312 | F8: =SUM(F4:F7) -> 53.6897 | G8: =SUM(G4:G7) -> 115.89401 | H8: Datos.Total | I8: =SUM(I6:I7) -> 0
B10: 2026 | C10: Apert.Op | D10: Cierre.Op | E10: Total | F10: T.Tobin | G10: Total
B11: Cta-1 | C11: ='2026'!N24 -> 6.759 | D11: ='2026'!O24 -> 7.02 | E11: =C11+D11 -> 13.779 | F11: ='2026'!P24 -> 11.265 | G11: =E11+F11 -> 25.044 | H11: Comisiones por Datos en Tiempo Real
B12: Cta-2 | C12: ='2026'!N29 -> 0 | D12: ='2026'!O29 -> 0 | E12: =C12+D12 -> 0 | F12: ='2026'!P29 -> 0 | G12: =E12+F12 -> 0 | H12: Datos.TR | I12: Ene | J12: Feb | K12: Mar | L12: Abr | M12: May | N12: Jun | O12: Jul | P12: Ago | Q12: Sep | R12: Oct | S12: Nov | T12: Dic | U12: Total
B13: Cta-3 | C13: ='2026'!N34 -> 0 | D13: ='2026'!O34 -> 0 | E13: =C13+D13 -> 0 | F13: ='2026'!P34 -> 0 | G13: =E13+F13 -> 0 | H13: Datos | U13: =SUM(I13:T13) -> 0
B14: Cta-4 | C14: ='2026'!N39 -> 0 | D14: ='2026'!O39 -> 0 | E14: =C14+D14 -> 0 | F14: ='2026'!P39 -> 0 | G14: =E14+F14 -> 0 | H14: Imp.Ventas | I14: =I13*0.21 -> 0 | J14: =J13*0.21 -> 0 | K14: =K13*0.21 -> 0 | L14: =L13*0.21 -> 0 | M14: =M13*0.21 -> 0 | N14: =N13*0.21 -> 0 | O14: =O13*0.21 -> 0 | P14: =P13*0.21 -> 0 | ... T14: =T13*0.21 -> 0 | U14: =SUM(I14:T14) -> 0
B15: Total | C15: =SUM(C11:C14) -> 6.759 | D15: =SUM(D11:D14) -> 7.02 | E15: =SUM(E11:E14) -> 13.779 | F15: =SUM(F11:F14) -> 11.265 | G15: =SUM(G11:G14) -> 25.044 | H15: Datos.Total | I15: =I13+I14 -> 0 | J15: =J13+J14 -> 0 | K15: =K13+K14 -> 0 | L15: =L13+L14 -> 0 | M15: =M13+M14 -> 0 | N15: =N13+N14 -> 0 | O15: =O13+O14 -> 0 | P15: =P13+P14 -> 0 | ... T15: =T13+T14 -> 0 | U15: =SUM(U13:U14) -> 0
B17: 2025 | C17: Apert.Op | D17: Cierre.Op | E17: Total | F17: T.Tobin | G17: Total
B18: Cta-1 | C18: ='2025'!N27 -> 18.08122 | D18: ='2025'!O27 -> 22.966492 | E18: =C18+D18 -> 41.047712 | F18: ='2025'!P27 -> 30.1287 | G18: =E18+F18 -> 71.176412 | H18: Comisiones por Datos en Tiempo Real
B19: Cta-2 | C19: ='2025'!N32 -> 0 | D19: ='2025'!O32 -> 0 | E19: =C19+D19 -> 0 | F19: ='2025'!P32 -> 0 | G19: =E19+F19 -> 0 | H19: Datos.TR | I19: Ene | J19: Feb | K19: Mar | L19: Abr | M19: May | N19: Jun | O19: Jul | P19: Ago | Q19: Sep | R19: Oct | S19: Nov | T19: Dic | U19: Total
B20: Cta-3 | C20: ='2025'!N37 -> 0 | D20: ='2025'!O37 -> 0 | E20: =C20+D20 -> 0 | F20: ='2025'!P37 -> 0 | G20: =E20+F20 -> 0 | H20: Datos | U20: =SUM(I20:T20) -> 0
B21: Cta-4 | C21: ='2025'!N42 -> 0 | D21: ='2025'!O42 -> 0 | E21: =C21+D21 -> 0 | F21: ='2025'!P42 -> 0 | G21: =E21+F21 -> 0 | H21: Imp.Ventas | U21: =SUM(I21:T21) -> 0
B22: Total | C22: =SUM(C18:C21) -> 18.08122 | D22: =SUM(D18:D21) -> 22.966492 | E22: =SUM(E18:E21) -> 41.047712 | F22: =SUM(F18:F21) -> 30.1287 | G22: =SUM(G18:G21) -> 71.176412 | H22: Datos.Total | I22: =I20+I21 -> 0 | J22: =J20+J21 -> 0 | K22: =K20+K21 -> 0 | L22: =L20+L21 -> 0 | M22: =M20+M21 -> 0 | N22: =N20+N21 -> 0 | O22: =O20+O21 -> 0 | P22: =P20+P21 -> 0 | ... T22: =T20+T21 -> 0 | U22: =SUM(U20:U21) -> 0

Sheet Dividendos
C2: Dividendos
C3: Cta-1 | F3: Cta-2 | I3: Cta-3 | L3: Cta-4 | O3: Div.Neto
C4: Bruto | D4: Imp 25% | E4: Neto | F4: Bruto | G4: Imp 25% | H4: Neto | I4: Bruto | J4: Imp 25% | K4: Neto | L4: Bruto | M4: Imp 25% | N4: Neto | O4: Total
B5: Total | C5: =D27+D20 -> 225 | D5: =E27+E20 -> 42.75 | E5: =F27+F20 -> 182.25 | F5: =H27+H20 -> 0 | G5: =I27+I20 -> 0 | H5: =J27+J20 -> 0 | I5: =L27+L20 -> 0 | J5: =M27+M20 -> 0 | K5: =N27+N20 -> 0 | L5: =P27+P20 -> 0 | M5: =Q27+Q20 -> 0 | N5: =R27+R20 -> 0 | O5: =S27+S20 -> 182.25
B7: 2026 | C7: Dividendos
C8: Cta-1 | G8: Cta-2 | K8: Cta-3 | O8: Cta-4 | S8: Div.Neto
B9: Mes | C9: Valor | D9: Bruto | E9: Imp 25% | F9: Neto | G9: Valor | H9: Bruto | I9: Imp 25% | J9: Neto | K9: Valor | L9: Bruto | M9: Imp 25% | N9: Neto | O9: Valor | P9: Bruto | Q9: Imp 25% | R9: Neto | S9: Total
B10: Ene
B11: Feb
B12: Mar
B13: Jun | J13: =H13-I13 -> 0 | N13: =L13-M13 -> 0 | R13: =P13-Q13 -> 0 | S13: =F13+J13+N13+R13 -> 0
B14: Jul | N14: =L14-M14 -> 0 | R14: =P14-Q14 -> 0 | S14: =F14+J14+N14+R14 -> 0
B15: Ago | F15: =D15-E15 -> 0 | J15: =H15-I15 -> 0 | N15: =L15-M15 -> 0 | R15: =P15-Q15 -> 0 | S15: =F15+J15+N15+R15 -> 0
B16: Sep | F16: =D16-E16 -> 0 | J16: =H16-I16 -> 0 | N16: =L16-M16 -> 0 | R16: =P16-Q16 -> 0 | S16: =F16+J16+N16+R16 -> 0
B17: Oct | F17: =D17-E17 -> 0 | J17: =H17-I17 -> 0 | N17: =L17-M17 -> 0 | R17: =P17-Q17 -> 0 | S17: =F17+J17+N17+R17 -> 0
B18: Nov | F18: =D18-E18 -> 0 | J18: =H18-I18 -> 0 | N18: =L18-M18 -> 0 | R18: =P18-Q18 -> 0 | S18: =F18+J18+N18+R18 -> 0
B19: Dic | F19: =D19-E19 -> 0 | J19: =H19-I19 -> 0 | N19: =L19-M19 -> 0 | R19: =P19-Q19 -> 0 | S19: =F19+J19+N19+R19 -> 0
C20: Total | D20: =SUM(D10:D19) -> 0 | E20: =SUM(E10:E19) -> 0 | F20: =SUM(F10:F19) -> 0 | G20: Total | H20: =SUM(H10:H19) -> 0 | I20: =SUM(I10:I19) -> 0 | J20: =SUM(J10:J19) -> 0 | K20: Total | L20: =SUM(L10:L19) -> 0 | M20: =SUM(M10:M19) -> 0 | N20: =SUM(N10:N19) -> 0 | O20: Total | P20: =SUM(P10:P19) -> 0 | Q20: =SUM(Q10:Q19) -> 0 | R20: =SUM(R10:R19) -> 0 | S20: =SUM(S13:S19) -> 0
B22: 2025 | C22: Dividendos
C23: Cta-1 | G23: Cta-2 | K23: Cta-3 | O23: Cta-4 | S23: Div.Neto
B24: Mes | C24: Valor | D24: Bruto | E24: Imp 25% | F24: Neto | G24: Valor | H24: Bruto | I24: Imp 25% | J24: Neto | K24: Valor | L24: Bruto | M24: Imp 25% | N24: Neto | O24: Valor | P24: Bruto | Q24: Imp 25% | R24: Neto | S24: Total
B25: Jul | N25: =L25-M25 -> 0 | R25: =P25-Q25 -> 0 | S25: =F25+J25+N25+R25 -> 0
B26: Dic | C26: TEF - Telefónica | D26: 225 | E26: 42.75 | F26: =D26-E26 -> 182.25 | N26: =L26-M26 -> 0 | R26: =P26-Q26 -> 0 | S26: =F26+J26+N26+R26 -> 182.25
C27: Total | D27: =SUM(D25:D26) -> 225 | E27: =SUM(E25:E26) -> 42.75 | F27: =SUM(F25:F26) -> 182.25 | G27: Total | H27: =SUM(H25:H26) -> 0 | I27: =SUM(I25:I26) -> 0 | J27: =SUM(J25:J26) -> 0 | K27: Total | L27: =SUM(L25:L26) -> 0 | M27: =SUM(M25:M26) -> 0 | N27: =SUM(N25:N26) -> 0 | O27: Total | P27: =SUM(P25:P26) -> 0 | Q27: =SUM(Q25:Q26) -> 0 | R27: =SUM(R25:R26) -> 0 | S27: =SUM(S25:S26) -> 182.25

Sheet 2026
B2: Año | C2: Invertido | D2: Ventas | E2: Res.Ops | F2: Rent | G2: Op | H2: Impuestos | J2: ResTot | K2: Div.Neto | L2: Com.Dat | M2: Res.Neto
B3: 2026 | C3: =C18+H18+M18+R18 -> 5639.259 | D3: =D18+I18+N18+S18 -> 5831.715 | E3: =E18+J18+O18+T18 -> 192.456 | F3: =E3/C3 -> 0.034127888 | G3: =G18+L18+Q18+V18 -> 1 | H3: {=_xlfn.IFS(E3<=6000,E3*0.19,IF(E3>6000,E3<=50000),E3*0.21,IF(E3>50000,E3<=200000),E3*0.23,IF(E3>200000,E3<=300000),E3*0.27,E3>300000,E3*0.28)} -> 36.56664 | I3: {=_xlfn.IFS(G3<=6000,"19%",IF(G3>6000,G3<=50000),"21%",IF(G3>50000,G3<=200000),"23%",IF(G3>200000,G3<=300000),"27%",G3>300000,"28%")} -> 19% | J3: =E3-H3 -> 155.88936 | K3: =Dividendos!S20 -> 0 | L3: =Comisiones!U15 -> 0 | M3: =J3+K3-L3 -> 155.88936
B4: 2026 | C4: Cta-1 | H4: Cta-2 | M4: Cta-3 | R4: Cta-4
B5: Mes | C5: Cap.Invertido | D5: Cap.Ventas | E5: Beneficio | F5: Rent | G5: Op | H5: Cap.Invertido | I5: Cap.Ventas | J5: Resultado | K5: Rent | L5: Op | M5: Cap.Invertido | N5: Cap.Ventas | O5: Resultado | P5: Rent | Q5: Op | R5: Cap.Invertido | S5: Cap.Ventas | T5: Resultado | U5: Rent | V5: Op
B6: Ene | C6: =SUMIF(S21:S22,"Ene",N21:N22)+SUMIF(S21:S22,"Ene",H21:H22) -> 0 | D6: =(SUMIF(S21:S22,"Ene",L21:L22))-((SUMIF(S21:S22,"Ene",P21:P22)+SUMIF(S21:S22,"Ene",O21:O22))) -> 0 | E6: =SUMIF(S21:S22,"Ene",Q21:Q22) -> 0 | G6: =COUNTIF(S21:S22,"Ene") -> 0 | H6: =SUMIF(S26:S27,"Ene",N26:N27)+SUMIF(S26:S27,"Ene",H26:H27) -> 0 | I6: =(SUMIF(S26:S27,"Ene",L26:L27))-((SUMIF(S26:S27,"Ene",P26:P27)+SUMIF(S26:S27,"Ene",O26:O27))) -> 0 | J6: =SUMIF(S26:S27,"Ene",Q26:Q27) -> 0 | K6: =J6/H6 -> #DIV/0! | L6: =COUNTIF(S26:S27,"Ene") -> 0 | M6: =SUMIF(S31:S32,"Ene",N31:N32)+SUMIF(S31:S32,"Ene",H31:H32) -> 0 | N6: =(SUMIF(S31:S32,"Ene",L31:L32))-((SUMIF(S31:S32,"Ene",P31:P32)+SUMIF(S31:S32,"Ene",O31:O32))) -> 0 | O6: =SUMIF(S31:S32,"Ene",Q31:Q32) -> 0 | P6: =O6/M6 -> #DIV/0! | Q6: =COUNTIF(S31:S32,"Ene") -> 0 | R6: =SUMIF(S36:S37,"Ene",N36:N37)+SUMIF(S36:S37,"Ene",H36:H37) -> 0 | S6: =(SUMIF(S36:S37,"Ene",L36:L37))-((SUMIF(S36:S37,"Ene",P36:P37)+SUMIF(S36:S37,"Ene",O36:O37))) -> 0 | T6: =SUMIF(S36:S37,"Ene",Q36:Q37) -> 0 | U6: =T6/R6 -> #DIV/0! | V6: =COUNTIF(S36:S37,"Ene") -> 0
B7: Feb | C7: =SUMIF(S21:S22,"Feb",N21:N22)+SUMIF(S21:S22,"Feb",H21:H22) -> 0 | D7: =(SUMIF(S21:S22,"Feb",L21:L22))-((SUMIF(S21:S22,"Feb",P21:P22)+SUMIF(S21:S22,"Feb",O21:O22))) -> 0 | E7: =SUMIF(S21:S22,"Feb",Q21:Q22) -> 0 | G7: =COUNTIF(S21:S22,"Feb") -> 0 | H7: =SUMIF(S26:S27,"Feb",N26:N27)+SUMIF(S26:S27,"Feb",H26:H27) -> 0 | I7: =(SUMIF(S26:S27,"Feb",L26:L27))-((SUMIF(S26:S27,"Feb",P26:P27)+SUMIF(S26:S27,"Feb",O26:O27))) -> 0 | J7: =SUMIF(S26:S27,"Feb",Q26:Q27) -> 0 | L7: =COUNTIF(S26:S27,"Feb") -> 0 | M7: =SUMIF(S31:S32,"Feb",N31:N32)+SUMIF(S31:S32,"Feb",H31:H32) -> 0 | N7: =(SUMIF(S31:S32,"Feb",L31:L32))-((SUMIF(S31:S32,"Feb",P31:P32)+SUMIF(S31:S32,"Feb",O31:O32))) -> 0 | O7: =SUMIF(S31:S32,"Feb",Q31:Q32) -> 0 | Q7: =COUNTIF(S31:S32,"Feb") -> 0 | R7: =SUMIF(S36:S37,"Feb",N36:N37)+SUMIF(S36:S37,"Feb",H36:H37) -> 0 | S7: =(SUMIF(S36:S37,"Feb",L36:L37))-((SUMIF(S36:S37,"Feb",P36:P37)+SUMIF(S36:S37,"Feb",O36:O37))) -> 0 | T7: =SUMIF(S36:S37,"Feb",Q36:Q37) -> 0 | V7: =COUNTIF(S36:S37,"Feb") -> 0
B8: Mar | C8: =SUMIF(S21:S22,"Mar",N21:N22)+SUMIF(S21:S22,"Mar",H21:H22) -> 0 | D8: =(SUMIF(S21:S22,"Mar",L21:L22))-((SUMIF(S21:S22,"Mar",P21:P22)+SUMIF(S21:S22,"Mar",O21:O22))) -> 0 | E8: =SUMIF(S21:S22,"Mar",Q21:Q22) -> 0 | G8: =COUNTIF(S21:S22,"Mar") -> 0 | H8: =SUMIF(S26:S27,"Mar",N26:N27)+SUMIF(S26:S27,"Mar",H26:H27) -> 0 | I8: =(SUMIF(S26:S27,"Mar",L26:L27))-((SUMIF(S26:S27,"Mar",P26:P27)+SUMIF(S26:S27,"Mar",O26:O27))) -> 0 | J8: =SUMIF(S26:S27,"Mar",Q26:Q27) -> 0 | L8: =COUNTIF(S26:S27,"Mar") -> 0 | M8: =SUMIF(S31:S32,"Mar",N31:N32)+SUMIF(S31:S32,"Mar",H31:H32) -> 0 | N8: =(SUMIF(S31:S32,"Mar",L31:L32))-((SUMIF(S31:S32,"Mar",P31:P32)+SUMIF(S31:S32,"Mar",O31:O32))) -> 0 | O8: =SUMIF(S31:S32,"Mar",Q31:Q32) -> 0 | Q8: =COUNTIF(S31:S32,"Mar") -> 0 | R8: =SUMIF(S36:S37,"Mar",N36:N37)+SUMIF(S36:S37,"Mar",H36:H37) -> 0 | S8: =(SUMIF(S36:S37,"Mar",L36:L37))-((SUMIF(S36:S37,"Mar",P36:P37)+SUMIF(S36:S37,"MAr",O36:O37))) -> 0 | T8: =SUMIF(S36:S37,"Mar",Q36:Q37) -> 0 | V8: =COUNTIF(S36:S37,"Mar") -> 0
B9: Abr | C9: =SUMIF(S21:S22,"Abr",N21:N22)+SUMIF(S21:S22,"Abr",H21:H22) -> 5639.259 | D9: =(SUMIF(S21:S22,"Abr",L21:L22))-((SUMIF(S21:S22,"Abr",P21:P22)+SUMIF(S21:S22,"Abr",O21:O22))) -> 5831.715 | E9: =SUMIF(S21:S22,"Abr",Q21:Q22) -> 192.456 | F9: =E9/C9 -> 0.034127888 | G9: =COUNTIF(S21:S22,"Abr") -> 1 | H9: =SUMIF(S26:S27,"Abr",N26:N27)+SUMIF(S26:S27,"Abr",H26:H27) -> 0 | I9: =(SUMIF(S26:S27,"Abr",L26:L27))-((SUMIF(S26:S27,"Abr",P26:P27)+SUMIF(S26:S27,"Abr",O26:O27))) -> 0 | J9: =SUMIF(S26:S27,"Abr",Q26:Q27) -> 0 | L9: =COUNTIF(S26:S27,"Abr") -> 0 | M9: =SUMIF(S31:S32,"Abr",N31:N32)+SUMIF(S31:S32,"Abr",H31:H32) -> 0 | N9: =(SUMIF(S31:S32,"Abr",L31:L32))-((SUMIF(S31:S32,"Abr",P31:P32)+SUMIF(S31:S32,"Abr",O31:O32))) -> 0 | O9: =SUMIF(S31:S32,"Abr",Q31:Q32) -> 0 | Q9: =COUNTIF(S31:S32,"Abr") -> 0 | R9: =SUMIF(S36:S37,"Abr",N36:N37)+SUMIF(S36:S37,"Abr",H36:H37) -> 0 | S9: =(SUMIF(S36:S37,"Abr",L36:L37))-((SUMIF(S36:S37,"Abr",P36:P37)+SUMIF(S36:S37,"Abr",O36:O37))) -> 0 | T9: =SUMIF(S36:S37,"Abr",Q36:Q37) -> 0 | V9: =COUNTIF(S36:S37,"Abr") -> 0
B10: May | C10: =SUMIF(S21:S22,"May",N21:N22)+SUMIF(S21:S22,"May",H21:H22) -> 0 | D10: =(SUMIF(S21:S22,"May",L21:L22))-((SUMIF(S21:S22,"May",P21:P22)+SUMIF(S21:S22,"May",O21:O22))) -> 0 | E10: =SUMIF(S21:S22,"May",Q21:Q22) -> 0 | G10: =COUNTIF(S21:S22,"May") -> 0 | H10: =SUMIF(S26:S27,"May",N26:N27)+SUMIF(S26:S27,"May",H26:H27) -> 0 | I10: =(SUMIF(S26:S27,"May",L26:L27))-((SUMIF(S26:S27,"My",P26:P27)+SUMIF(S26:S27,"May",O26:O27))) -> 0 | J10: =SUMIF(S26:S27,"May",Q26:Q27) -> 0 | L10: =COUNTIF(S26:S27,"May") -> 0 | M10: =SUMIF(S31:S32,"May",N31:N32)+SUMIF(S31:S32,"May",H31:H32) -> 0 | N10: =(SUMIF(S31:S32,"May",L31:L32))-((SUMIF(S31:S32,"May",P31:P32)+SUMIF(S31:S32,"May",O31:O32))) -> 0 | O10: =SUMIF(S31:S32,"May",Q31:Q32) -> 0 | Q10: =COUNTIF(S31:S32,"May") -> 0 | R10: =SUMIF(S36:S37,"May",N36:N37)+SUMIF(S36:S37,"May",H36:H37) -> 0 | S10: =(SUMIF(S36:S37,"May",L36:L37))-((SUMIF(S36:S37,"May",P36:P37)+SUMIF(S36:S37,"May",O36:O37))) -> 0 | T10: =SUMIF(S36:S37,"May",Q36:Q37) -> 0 | V10: =COUNTIF(S36:S37,"May") -> 0
B11: Jun | C11: =SUMIF(S21:S22,"Jun",N21:N22)+SUMIF(S21:S22,"Jun",H21:H22) -> 0 | D11: =(SUMIF(S21:S22,"Jun",L21:L22))-((SUMIF(S21:S22,"Jun",P21:P22)+SUMIF(S21:S22,"Jun",O21:O22))) -> 0 | E11: =SUMIF(S21:S22,"Jun",Q21:Q22) -> 0 | G11: =COUNTIF(S21:S22,"Jun") -> 0 | H11: =SUMIF(S26:S27,"Jun",N26:N27)+SUMIF(S26:S27,"Jun",H26:H27) -> 0 | I11: =(SUMIF(S26:S27,"Jun",L26:L27))-((SUMIF(S26:S27,"Jun",P26:P27)+SUMIF(S26:S27,"Jun",O26:O27))) -> 0 | J11: =SUMIF(S26:S27,"Jun",Q26:Q27) -> 0 | L11: =COUNTIF(S26:S27,"Jun") -> 0 | M11: =SUMIF(S31:S32,"Jun",N31:N32)+SUMIF(S31:S32,"Jun",H31:H32) -> 0 | N11: =(SUMIF(S31:S32,"Jun",L31:L32))-((SUMIF(S31:S32,"Jun",P31:P32)+SUMIF(S31:S32,"Jun",O31:O32))) -> 0 | O11: =SUMIF(S31:S32,"Jun",Q31:Q32) -> 0 | Q11: =COUNTIF(S31:S32,"Jun") -> 0 | R11: =SUMIF(S36:S37,"Jun",N36:N37)+SUMIF(S36:S37,"Jun",H36:H37) -> 0 | S11: =(SUMIF(S36:S37,"Jun",L36:L37))-((SUMIF(S36:S37,"Jun",P36:P37)+SUMIF(S36:S37,"Jun",O36:O37))) -> 0 | T11: =SUMIF(S36:S37,"Jun",Q36:Q37) -> 0 | V11: =COUNTIF(S36:S37,"Jun") -> 0
B12: Jul | C12: =SUMIF(S21:S22,"Jul",N21:N22)+SUMIF(S21:S22,"Jul",H21:H22) -> 0 | D12: =(SUMIF(S21:S22,"Jul",L21:L22))-((SUMIF(S21:S22,"Jul",P21:P22)+SUMIF(S21:S22,"Jul",O21:O22))) -> 0 | E12: =SUMIF(S21:S22,"Jul",Q21:Q22) -> 0 | G12: =COUNTIF(S21:S22,"Jul") -> 0 | H12: =SUMIF(S26:S27,"Jul",N26:N27)+SUMIF(S26:S27,"Jul",H26:H27) -> 0 | I12: =(SUMIF(S26:S27,"Jul",L26:L27))-((SUMIF(S26:S27,"Jul",P26:P27)+SUMIF(S26:S27,"Jul",O26:O27))) -> 0 | J12: =SUMIF(S26:S27,"Jul",Q26:Q27) -> 0 | L12: =COUNTIF(S26:S27,"Jul") -> 0 | M12: =SUMIF(S31:S32,"Jul",N31:N32)+SUMIF(S31:S32,"Jul",H31:H32) -> 0 | N12: =(SUMIF(S31:S32,"Jul",L31:L32))-((SUMIF(S31:S32,"Jul",P31:P32)+SUMIF(S31:S32,"Jul",O31:O32))) -> 0 | O12: =SUMIF(S31:S32,"Jul",Q31:Q32) -> 0 | Q12: =COUNTIF(S31:S32,"Jul") -> 0 | R12: =SUMIF(S36:S37,"Jul",N36:N37)+SUMIF(S36:S37,"Jul",H36:H37) -> 0 | S12: =(SUMIF(S36:S37,"Jul",L36:L37))-((SUMIF(S36:S37,"Jul",P36:P37)+SUMIF(S36:S37,"Jul",O36:O37))) -> 0 | T12: =SUMIF(S36:S37,"Jul",Q36:Q37) -> 0 | V12: =COUNTIF(S36:S37,"Jul") -> 0
B13: Ago | C13: =SUMIF(S21:S22,"Ago",N21:N22)+SUMIF(S21:S22,"Ago",H21:H22) -> 0 | D13: =(SUMIF(S21:S22,"Ago",L21:L22))-((SUMIF(S21:S22,"Ago",P21:P22)+SUMIF(S21:S22,"Ago",O21:O22))) -> 0 | E13: =SUMIF(S21:S22,"Ago",Q21:Q22) -> 0 | G13: =COUNTIF(S21:S22,"Ago") -> 0 | H13: =SUMIF(S26:S27,"Ago",N26:N27)+SUMIF(S26:S27,"Ago",H26:H27) -> 0 | I13: =(SUMIF(S26:S27,"Ago",L26:L27))-((SUMIF(S26:S27,"Ago",P26:P27)+SUMIF(S26:S27,"Ago",O26:O27))) -> 0 | J13: =SUMIF(S26:S27,"Ago",Q26:Q27) -> 0 | L13: =COUNTIF(S26:S27,"Ago") -> 0 | M13: =SUMIF(S31:S32,"Ago",N31:N32)+SUMIF(S31:S32,"Ago",H31:H32) -> 0 | N13: =(SUMIF(S31:S32,"Ago",L31:L32))-((SUMIF(S31:S32,"Ago",P31:P32)+SUMIF(S31:S32,"Ago",O31:O32))) -> 0 | O13: =SUMIF(S31:S32,"Jul",Q31:Q32) -> 0 | Q13: =COUNTIF(S31:S32,"Ago") -> 0 | R13: =SUMIF(S36:S37,"Ago",N36:N37)+SUMIF(S36:S37,"Ago",H36:H37) -> 0 | S13: =(SUMIF(S36:S37,"Ago",L36:L37))-((SUMIF(S36:S37,"Ago",P36:P37)+SUMIF(S36:S37,"Ago",O36:O37))) -> 0 | T13: =SUMIF(S36:S37,"Ago",Q36:Q37) -> 0 | V13: =COUNTIF(S36:S37,"Ago") -> 0
B14: Sep | C14: =SUMIF(S21:S22,"Sep",N21:N22)+SUMIF(S21:S22,"Sep",H21:H22) -> 0 | D14: =(SUMIF(S21:S22,"Sep",L21:L22))-((SUMIF(S21:S22,"Sep",P21:P22)+SUMIF(S21:S22,"Sep",O21:O22))) -> 0 | E14: =SUMIF(S21:S22,"Sep",Q21:Q22) -> 0 | G14: =COUNTIF(S21:S22,"Sep") -> 0 | H14: =SUMIF(S26:S27,"Sep",N26:N27)+SUMIF(S26:S27,"Sep",H26:H27) -> 0 | I14: =(SUMIF(S26:S27,"Sep",L26:L27))-((SUMIF(S26:S27,"Sep",P26:P27)+SUMIF(S26:S27,"Sep",O26:O27))) -> 0 | J14: =SUMIF(S26:S27,"Sep",Q26:Q27) -> 0 | L14: =COUNTIF(S26:S27,"Sep") -> 0 | M14: =SUMIF(S31:S32,"Sep",N31:N32)+SUMIF(S31:S32,"Sep",H31:H32) -> 0 | N14: =(SUMIF(S31:S32,"Sep",L31:L32))-((SUMIF(S31:S32,"Sep",P31:P32)+SUMIF(S31:S32,"Sep",O31:O32))) -> 0 | O14: =SUMIF(S31:S32,"Sep",Q31:Q32) -> 0 | Q14: =COUNTIF(S31:S32,"Sep") -> 0 | R14: =SUMIF(S36:S37,"Sep",N36:N37)+SUMIF(S36:S37,"Sep",H36:H37) -> 0 | S14: =(SUMIF(S36:S37,"Sep",L36:L37))-((SUMIF(S36:S37,"Sep",P36:P37)+SUMIF(S36:S37,"Sep",O36:O37))) -> 0 | T14: =SUMIF(S36:S37,"Sep",Q36:Q37) -> 0 | V14: =COUNTIF(S36:S37,"Sep") -> 0
B15: Oct | C15: =SUMIF(S21:S22,"Oct",N21:N22)+SUMIF(S21:S22,"Oct",H21:H22) -> 0 | D15: =(SUMIF(S21:S22,"Oct",L21:L22))-((SUMIF(S21:S22,"Oct",P21:P22)+SUMIF(S21:S22,"OCt",O21:O22))) -> 0 | E15: =SUMIF(S21:S22,"Oct",Q21:Q22) -> 0 | G15: =COUNTIF(S21:S21,"Oct") -> 0 | H15: =SUMIF(S26:S27,"Oct",N26:N27)+SUMIF(S26:S27,"Oct",H26:H27) -> 0 | I15: =(SUMIF(S26:S27,"Oct",L26:L27))-((SUMIF(S26:S27,"Oct",P26:P27)+SUMIF(S26:S27,"Oct",O26:O27))) -> 0 | J15: =SUMIF(S26:S27,"Oct",Q26:Q27) -> 0 | L15: =COUNTIF(S26:S27,"Oct") -> 0 | M15: =SUMIF(S31:S32,"Oct",N31:N32)+SUMIF(S31:S32,"Oct",H31:H32) -> 0 | N15: =(SUMIF(S31:S32,"Oct",L31:L32))-((SUMIF(S31:S32,"Oct",P31:P32)+SUMIF(S31:S32,"Oct",O31:O32))) -> 0 | O15: =SUMIF(S31:S32,"Oct",Q31:Q32) -> 0 | Q15: =COUNTIF(S31:S32,"Oct") -> 0 | R15: =SUMIF(S36:S37,"Oct",N36:N37)+SUMIF(S36:S37,"Oct",H36:H37) -> 0 | S15: =(SUMIF(S36:S37,"Oct",L36:L37))-((SUMIF(S36:S37,"Oct",P36:P37)+SUMIF(S36:S37,"Oct",O36:O37))) -> 0 | T15: =SUMIF(S36:S37,"Oct",Q36:Q37) -> 0 | V15: =COUNTIF(S36:S37,"Oct") -> 0
B16: Nov | C16: =SUMIF(S21:S22,"Nov",N21:N22)+SUMIF(S21:S22,"Nov",H21:H22) -> 0 | D16: =(SUMIF(S21:S22,"Nov",L21:L22))-((SUMIF(S21:S22,"Nov",P21:P22)+SUMIF(S21:S22,"Nov",O21:O22))) -> 0 | E16: =SUMIF(S21:S22,"Nov",Q21:Q22) -> 0 | G16: =COUNTIF(S21:S22,"Nov") -> 0 | H16: =SUMIF(S26:S27,"Nov",N26:N27)+SUMIF(S26:S27,"Nov",H26:H27) -> 0 | I16: =(SUMIF(S26:S27,"Nov",L26:L27))-((SUMIF(S26:S27,"Nov",P26:P27)+SUMIF(S26:S27,"Nov",O26:O27))) -> 0 | J16: =SUMIF(S26:S27,"Nov",Q26:Q27) -> 0 | L16: =COUNTIF(S26:S27,"Nov") -> 0 | M16: =SUMIF(S31:S32,"Nov",N31:N32)+SUMIF(S31:S32,"Nov",H31:H32) -> 0 | N16: =(SUMIF(S31:S32,"Nov",L31:L32))-((SUMIF(S31:S32,"Nov",P31:P32)+SUMIF(S31:S32,"Nov",O31:O32))) -> 0 | O16: =SUMIF(S31:S32,"Nov",Q31:Q32) -> 0 | Q16: =COUNTIF(S31:S32,"Nov") -> 0 | R16: =SUMIF(S36:S37,"Nov",N36:N37)+SUMIF(S36:S37,"Nov",H36:H37) -> 0 | S16: =(SUMIF(S36:S37,"Nov",L36:L37))-((SUMIF(S36:S37,"Nov",P36:P37)+SUMIF(S36:S37,"Nov",O36:O37))) -> 0 | T16: =SUMIF(S36:S37,"Nov",Q36:Q37) -> 0 | V16: =COUNTIF(S36:S37,"Nov") -> 0
B17: Dic | C17: =SUMIF(S21:S22,"Dic",N21:N22)+SUMIF(S21:S22,"Dic",H21:H22) -> 0 | D17: =(SUMIF(S21:S22,"Dic",L21:L22))-((SUMIF(S21:S22,"Dic",P21:P22)+SUMIF(S21:S22,"Dic",O21:O22))) -> 0 | E17: =SUMIF(S21:S22,"Dic",Q21:Q22) -> 0 | G17: =COUNTIF(S21:S21,"Dic") -> 0 | H17: =SUMIF(S26:S27,"Dic",N26:N27)+SUMIF(S26:S27,"Dic",H26:H27) -> 0 | I17: =(SUMIF(S26:S27,"Dic",L26:L27))-((SUMIF(S26:S27,"Dic",P26:P27)+SUMIF(S26:S27,"Dic",O26:O27))) -> 0 | J17: =SUMIF(S26:S27,"Dic",Q26:Q27) -> 0 | L17: =COUNTIF(S26:S27,"Dic") -> 0 | M17: =SUMIF(S31:S32,"Dic",N31:N32)+SUMIF(S31:S32,"Dic",H31:H32) -> 0 | N17: =(SUMIF(S31:S32,"Dic",L31:L32))-((SUMIF(S31:S32,"Dic",P31:P32)+SUMIF(S31:S32,"Dic",O31:O32))) -> 0 | O17: =SUMIF(S31:S32,"Dic",Q31:Q32) -> 0 | Q17: =COUNTIF(S31:S32,"Dic") -> 0 | R17: =SUMIF(S36:S37,"Dic",N36:N37)+SUMIF(S36:S37,"Dic",H36:H37) -> 0 | S17: =(SUMIF(S36:S37,"Dic",L36:L37))-((SUMIF(S36:S37,"Dic",P36:P37)+SUMIF(S36:S37,"Dic",O36:O37))) -> 0 | T17: =SUMIF(S36:S37,"Dic",Q36:Q37) -> 0 | V17: =COUNTIF(S36:S37,"Dic") -> 0
B18: Total | C18: =SUM(C6:C17) -> 5639.259 | D18: =SUM(D6:D17) -> 5831.715 | E18: =SUM(E6:E17) -> 192.456 | F18: =E18/C18 -> 0.034127888 | G18: =SUM(G6:G17) -> 1 | H18: =SUM(H6:H17) -> 0 | I18: =SUM(I6:I17) -> 0 | J18: =SUM(J6:J17) -> 0 | K18: =J18/H18 -> #DIV/0! | L18: =SUM(L6:L17) -> 0 | M18: =SUM(M6:M17) -> 0 | N18: =SUM(N6:N17) -> 0 | O18: =SUM(O6:O17) -> 0 | P18: =O18/M18 -> #DIV/0! | Q18: =SUM(Q6:Q17) -> 0 | R18: =SUM(R6:R17) -> 0 | S18: =SUM(S6:S17) -> 0 | T18: =S18-R18 -> 0 | U18: =T18/R18 -> #DIV/0! | V18: =SUM(V6:V17) -> 0
B20: Cuenta | C20: Valor | D20: Nº Op. | E20: Apertura | F20: Acciones | G20: Pr.Compra | H20: Compra € | I20: Cierre | J20: Pr.Venta | K20: BnfxAcc | L20: Venta € | M20: Res.Venta | N20: Com.Op.Ap | O20: Com.Op.Cierr | P20: T.Tobin | Q20: BnfNeto | R20: Rent | S20: Mes.Cierre | T20: Estado
B21: Cta-1
C22: TEF - Telefónica | D22: 1 | E22: 45965 | F22: 1500 | G22: 3.755 | H22: =G22*F22 -> 5632.5 | I22: 46119 | J22: 3.9 | K22: =J22-G22 -> 0.145 | L22: =F22*J22 -> 5850 | M22: =F22*K22 -> 217.5 | N22: {=_xlfn.IFS(E22="",0,H22<4166.67,5,H22>4166.67,H22*0.12%)} -> 6.759 | O22: {=_xlfn.IFS(I22="",0,L22<4166.67,5,L22>4166.67,L22*0.12%)} -> 7.02 | P22: =H22*0.002 -> 11.265 | Q22: =M22-(N22+O22+P22) -> 192.456 | R22: =Q22/H22 -> 0.034168842 | S22: Abr | T22: Cerrada
D23: Operaciones | E23: Cap.Apertura | F23: Acc.Tot | G23: PrC.Prom | H23: Compra.Tot | I23: Cap.Venta | J23: PrV.Prom | K23: BnfxAcc.Tot | L23: Venta.Tot | M23: Res.Tot | N23: Com.Ap.Tot | O23: Com.Cierr.Tot | P23: T.Tobin | Q23: Bnf.Tot | R23: Rent | S23: Res.Tot | T23: Res-Tobin
D24: =COUNTA(E21:E22) -> 1 | E24: =H24+N24 -> 5639.259 | F24: =SUM(F21:F22) -> 1500 | G24: =AVERAGE(G21:G22) -> 3.755 | H24: =SUM(H21:H22) -> 5632.5 | I24: =L24-(O24+P24) -> 5831.715 | J24: =AVERAGE(J21:J22) -> 3.9 | K24: =SUM(K21:K22) -> 0.145 | L24: =SUM(L21:L22) -> 5850 | M24: =SUM(M21:M22) -> 217.5 | N24: =SUM(N21:N22) -> 6.759 | O24: =SUM(O21:O22) -> 7.02 | P24: =SUM(P21:P22) -> 11.265 | Q24: =SUM(Q21:Q22) -> 192.456 | R24: =Q24/H24 -> 0.034168842 | S24: =SUM(P21:Q22) -> 203.721 | T24: =I24-E24 -> 192.456
B25: Cuenta | C25: Valor | D25: Nº Op. | E25: Apertura | F25: Acciones | G25: Pr.Compra | H25: Compra € | I25: Cierre | J25: Pr.Venta | K25: BnfxAcc | L25: Venta € | M25: Res.Venta | N25: Com.Op.Ap | O25: Com.Op.Cierr | P25: T.Tobin | Q25: BnfNeto | R25: Rent | S25: Mes.Cierre | T25: Estado
B26: Cta-2
D28: Operaciones | E28: Cap.Apertura | F28: Acc.Tot | G28: PrC.Prom | H28: Compra.Tot | I28: Cap.Venta | J28: PrV.Prom | K28: BnfxAcc.Tot | L28: Venta.Tot | M28: Res.Tot | N28: Com.Ap.Tot | O28: Com.Cierr.Tot | P28: T.Tobin | Q28: Bnf.Tot | R28: Rent | S28: Res.Tot | T28: Res-Tobin
D29: =COUNTA(E26:E27) -> 0 | E29: =H29+N29 -> 0 | F29: =SUM(F26:F27) -> 0 | G29: =AVERAGE(G26:G27) -> #DIV/0! | H29: =SUM(H26:H27) -> 0 | I29: =L29-(O29+P29) -> 0 | J29: =AVERAGE(J26:J27) -> #DIV/0! | K29: =SUM(K26:K27) -> 0 | L29: =SUM(L26:L27) -> 0 | M29: =SUM(M26:M27) -> 0 | N29: =SUM(N26:N27) -> 0 | O29: =SUM(O26:O27) -> 0 | P29: =SUM(P26:P27) -> 0 | Q29: =SUM(Q26:Q27) -> 0 | R29: =Q29/H29 -> #DIV/0! | S29: =SUM(P26:Q27) -> 0 | T29: =I29-E29 -> 0
B30: Cuenta | C30: Valor | D30: Nº Op. | E30: Apertura | F30: Acciones | G30: Pr.Compra | H30: Capital | I30: Cierre | J30: Pr.Venta | K30: BnfxAcc | L30: Venta € | M30: Res.Venta | N30: Com.Op.Ap | O30: Com.Op.Cierr | P30: T.Tobin | Q30: BnfNeto | R30: Rent | S30: Mes.Cierre | T30: Estado
B31: Cta-3
D33: Operaciones | E33: Cap.Apertura | F33: Acc.Tot | G33: PrC.Prom | H33: Compra.Tot | I33: Cap.Venta | J33: PrV.Prom | K33: BnfxAcc.Tot | L33: Venta.Tot | M33: Res.Tot | N33: Com.Ap.Tot | O33: Com.Cierr.Tot | P33: T.Tobin | Q33: Bnf.Tot | R33: Rent | S33: Res.Tot | T33: Res-Tobin
D34: =COUNTA(E31:E32) -> 0 | E34: =H34+N34 -> 0 | F34: =SUM(F31:F32) -> 0 | G34: =AVERAGE(G31:G32) -> #DIV/0! | H34: =SUM(H31:H32) -> 0 | I34: =L34-(O34+P34) -> 0 | J34: =AVERAGE(J31:J32) -> #DIV/0! | K34: =SUM(K31:K32) -> 0 | L34: =SUM(L31:L32) -> 0 | M34: =SUM(M31:M32) -> 0 | N34: =SUM(N31:N32) -> 0 | O34: =SUM(O31:O32) -> 0 | P34: =SUM(P31:P32) -> 0 | Q34: =SUM(Q31:Q32) -> 0 | R34: =Q34/H34 -> #DIV/0! | S34: =SUM(P31:Q32) -> 0 | T34: =I34-E34 -> 0
B35: Cuenta | C35: Valor | D35: Nº Op. | E35: Apertura | F35: Acciones | G35: Pr.Compra | H35: Capital | I35: Cierre | J35: Pr.Venta | K35: BnfxAcc | L35: Venta € | M35: Res.Venta | N35: Com.Op.Ap | O35: Com.Op.Cierr | P35: T.Tobin | Q35: BnfNeto | R35: Rent | S35: Mes.Cierre | T35: Estado
B36: Cta-4
D38: Operaciones | E38: Cap.Apertura | F38: Acc.Tot | G38: PrC.Prom | H38: Compra.Tot | I38: Cap.Venta | J38: PrV.Prom | K38: BnfxAcc.Tot | L38: Venta.Tot | M38: Res.Tot | N38: Com.Ap.Tot | O38: Com.Cierr.Tot | P38: T.Tobin | Q38: Bnf.Tot | R38: Rent | S38: Res.Tot | T38: Res-Tobin
D39: =COUNTA(E36:E37) -> 0 | E39: =H39+N39 -> 0 | F39: =SUM(F36:F37) -> 0 | G39: =AVERAGE(G36:G37) -> #DIV/0! | H39: =SUM(H36:H37) -> 0 | I39: =L39-(O39+P39) -> 0 | J39: =AVERAGE(J36:J37) -> #DIV/0! | K39: =SUM(K36:K37) -> 0 | L39: =SUM(L36:L37) -> 0 | M39: =SUM(M36:M37) -> 0 | N39: =SUM(N36:N37) -> 0 | O39: =SUM(O36:O37) -> 0 | P39: =SUM(P36:P37) -> 0 | Q39: =SUM(Q36:Q37) -> 0 | R39: =Q39/H39 -> #DIV/0! | S39: =SUM(P36:Q37) -> 0 | T39: =I39-E39 -> 0

Sheet 2025
B2: Año | C2: Invertido | D2: Ventas | E2: Res.Ops | F2: Rent | G2: Op | H2: Impuestos | J2: ResTot | K2: Div.Neto | L2: Com.Dat | M2: Res.Neto
B3: 2025 | C3: =C18+H18+M18+R18 -> 15083.431 | D3: =D18+I18+N18+S18 -> 16002.115 | E3: =E18+J18+O18+T18 -> 918.68359 | F3: =E3/C3 -> 0.060906804 | G3: =G18+L18+Q18+V18 -> 4 | H3: =E3*0.25 -> 229.6709 | I3: ="25%" -> 25% | J3: =E3-H3 -> 689.01269 | K3: =Dividendos!S27 -> 182.25 | L3: =Comisiones!U22 -> 0 | M3: =J3+K3-L3 -> 871.26269
B4: 2025 | C4: Cta-1 | H4: Cta-2 | M4: Cta-3 | R4: Cta-4
B5: Mes | C5: Cap.Invertido | D5: Cap.Ventas | E5: Beneficio | F5: Rent | G5: Op | H5: Cap.Invertido | I5: Cap.Ventas | J5: Resultado | K5: Rent | L5: Op | M5: Cap.Invertido | N5: Cap.Ventas | O5: Resultado | P5: Rent | Q5: Op | R5: Cap.Invertido | S5: Cap.Ventas | T5: Resultado | U5: Rent | V5: Op
B6: Ene | C6: =SUMIF(S21:S25,"Ene",N21:N25)+SUMIF(S21:S25,"Ene",H21:H25) -> 0 | D6: =(SUMIF(S21:S25,"Ene",L21:L25))-((SUMIF(S21:S25,"Ene",P21:P25)+SUMIF(S21:S25,"Ene",O21:O25))) -> 0 | E6: =SUMIF(S21:S25,"Ene",Q21:Q25) -> 0 | F6: =E6/C6 -> #DIV/0! | G6: =COUNTIF(S21:S25,"Ene") -> 0 | H6: =SUMIF(S29:S30,"Ene",N29:N30)+SUMIF(S29:S30,"Ene",H29:H30) -> 0 | I6: =(SUMIF(S29:S30,"Ene",L29:L30))-((SUMIF(S29:S30,"Ene",P29:P30)+SUMIF(S29:S30,"Ene",O29:O30))) -> 0 | J6: =SUMIF(S29:S30,"Ene",Q29:Q30) -> 0 | K6: =J6/H6 -> #DIV/0! | L6: =COUNTIF(S29:S30,"Ene") -> 0 | M6: =SUMIF(S34:S35,"Ene",N34:N35)+SUMIF(S34:S35,"Ene",H34:H35) -> 0 | N6: =(SUMIF(S34:S35,"Ene",L34:L35))-((SUMIF(S34:S35,"Ene",P34:P35)+SUMIF(S34:S35,"Ene",O34:O35))) -> 0 | O6: =SUMIF(S34:S35,"Ene",Q34:Q35) -> 0 | P6: =O6/M6 -> #DIV/0! | Q6: =COUNTIF(S34:S35,"Ene") -> 0 | R6: =SUMIF(S39:S40,"Ene",N39:N40)+SUMIF(S39:S40,"Ene",H39:H40) -> 0 | S6: =(SUMIF(S39:S40,"Ene",L39:L40))-((SUMIF(S39:S40,"Ene",P39:P40)+SUMIF(S39:S40,"Ene",O39:O40))) -> 0 | T6: =S6/Q6 -> #DIV/0! | V6: =COUNTIF(S39:S40,"Ene") -> 0
B7: Feb | C7: =SUMIF(S21:S25,"Feb",N21:N25)+SUMIF(S21:S25,"Feb",H21:H25) -> 0 | D7: =(SUMIF(S21:S25,"Feb",L21:L25))-((SUMIF(S21:S25,"Feb",P21:P25)+SUMIF(S21:S25,"Feb",O21:O25))) -> 0 | E7: =SUMIF(S21:S25,"Feb",Q21:Q25) -> 0 | G7: =COUNTIF(S21:S25,"Feb") -> 0 | H7: =SUMIF(S29:S30,"Feb",N29:N30)+SUMIF(S29:S30,"Feb",H29:H30) -> 0 | I7: =(SUMIF(S29:S30,"Feb",L29:L30))-((SUMIF(S29:S30,"Feb",P29:P30)+SUMIF(S29:S30,"Feb",O29:O30))) -> 0 | J7: =SUMIF(S29:S30,"Feb",Q29:Q30) -> 0 | L7: =COUNTIF(S29:S30,"Feb") -> 0 | M7: =SUMIF(S34:S35,"Feb",N34:N35)+SUMIF(S34:S35,"Feb",H34:H35) -> 0 | N7: =(SUMIF(S34:S35,"Feb",L34:L35))-((SUMIF(S34:S35,"Feb",P34:P35)+SUMIF(S34:S35,"Feb",O34:O35))) -> 0 | O7: =SUMIF(S34:S35,"Feb",Q34:Q35) -> 0 | Q7: =COUNTIF(S34:S35,"Feb") -> 0 | R7: =SUMIF(S39:S40,"Feb",N39:N40)+SUMIF(S39:S40,"Feb",H39:H40) -> 0 | S7: =(SUMIF(S39:S40,"Feb",L39:L40))-((SUMIF(S39:S40,"Feb",P39:P40)+SUMIF(S39:S40,"Feb",O39:O40))) -> 0 | T7: =SUMIF(S39:S40,"Feb",Q39:Q40) -> 0 | V7: =COUNTIF(S39:S40,"Feb") -> 0
B8: Mar | C8: =SUMIF(S21:S25,"Mar",N21:N25)+SUMIF(S21:S25,"Mar",H21:H25) -> 0 | D8: =(SUMIF(S21:S25,"Mar",L21:L25))-((SUMIF(S21:S25,"Mar",P21:P25)+SUMIF(S21:S25,"Mar",O21:O25))) -> 0 | E8: =SUMIF(S21:S25,"Mar",Q21:Q25) -> 0 | G8: =COUNTIF(S21:S25,"Mar") -> 0 | H8: =SUMIF(S29:S30,"Mar",N29:N30)+SUMIF(S29:S30,"Mar",H29:H30) -> 0 | I8: =(SUMIF(S29:S30,"Mar",L29:L30))-((SUMIF(S29:S30,"Mar",P29:P30)+SUMIF(S29:S30,"Mar",O29:O30))) -> 0 | J8: =SUMIF(S29:S30,"Mar",Q29:Q30) -> 0 | L8: =COUNTIF(S29:S30,"Mar") -> 0 | M8: =SUMIF(S34:S35,"Mar",N34:N35)+SUMIF(S34:S35,"Mar",H34:H35) -> 0 | N8: =(SUMIF(S34:S35,"Mar",L34:L35))-((SUMIF(S34:S35,"Mar",P34:P35)+SUMIF(S34:S35,"Mar",O34:O35))) -> 0 | O8: =SUMIF(S34:S35,"Mar",Q34:Q35) -> 0 | Q8: =COUNTIF(S34:S35,"Mar") -> 0 | R8: =SUMIF(S39:S40,"Mar",N39:N40)+SUMIF(S39:S40,"Mar",H39:H40) -> 0 | S8: =(SUMIF(S39:S40,"Mar",L39:L40))-((SUMIF(S39:S40,"Mar",P39:P40)+SUMIF(S39:S40,"MAr",O39:O40))) -> 0 | T8: =SUMIF(S39:S40,"Mar",Q39:Q40) -> 0 | V8: =COUNTIF(S39:S40,"Mar") -> 0
B9: Abr | C9: =SUMIF(S21:S25,"Abr",N21:N25)+SUMIF(S21:S25,"Abr",H21:H25) -> 0 | D9: =(SUMIF(S21:S25,"Abr",L21:L25))-((SUMIF(S21:S25,"Abr",P21:P25)+SUMIF(S21:S25,"Abr",O21:O25))) -> 0 | E9: =SUMIF(S21:S25,"Abr",Q21:Q25) -> 0 | G9: =COUNTIF(S21:S25,"Abr") -> 0 | H9: =SUMIF(S29:S30,"Abr",N29:N30)+SUMIF(S29:S30,"Abr",H29:H30) -> 0 | I9: =(SUMIF(S29:S30,"Abr",L29:L30))-((SUMIF(S29:S30,"Abr",P29:P30)+SUMIF(S29:S30,"Abr",O29:O30))) -> 0 | J9: =SUMIF(S29:S30,"Abr",Q29:Q30) -> 0 | L9: =COUNTIF(S29:S30,"Abr") -> 0 | M9: =SUMIF(S34:S35,"Abr",N34:N35)+SUMIF(S34:S35,"Abr",H34:H35) -> 0 | N9: =(SUMIF(S34:S35,"Abr",L34:L35))-((SUMIF(S34:S35,"Abr",P34:P35)+SUMIF(S34:S35,"Abr",O34:O35))) -> 0 | O9: =SUMIF(S34:S35,"Abr",Q34:Q35) -> 0 | Q9: =COUNTIF(S34:S35,"Abr") -> 0 | R9: =SUMIF(S39:S40,"Abr",N39:N40)+SUMIF(S39:S40,"Abr",H39:H40) -> 0 | S9: =(SUMIF(S39:S40,"Abr",L39:L40))-((SUMIF(S39:S40,"Abr",P39:P40)+SUMIF(S39:S40,"Abr",O39:O40))) -> 0 | T9: =SUMIF(S39:S40,"Abr",Q39:Q40) -> 0 | V9: =COUNTIF(S39:S40,"Abr") -> 0
B10: May | C10: =SUMIF(S21:S25,"May",N21:N25)+SUMIF(S21:S25,"May",H21:H25) -> 0 | D10: =(SUMIF(S21:S25,"May",L21:L25))-((SUMIF(S21:S25,"May",P21:P25)+SUMIF(S21:S25,"May",O21:O25))) -> 0 | E10: =SUMIF(S21:S25,"May",Q21:Q25) -> 0 | G10: =COUNTIF(S21:S25,"May") -> 0 | H10: =SUMIF(S29:S30,"May",N29:N30)+SUMIF(S29:S30,"May",H29:H30) -> 0 | I10: =(SUMIF(S29:S30,"May",L29:L30))-((SUMIF(S29:S30,"My",P29:P30)+SUMIF(S29:S30,"May",O29:O30))) -> 0 | J10: =SUMIF(S29:S30,"May",Q29:Q30) -> 0 | L10: =COUNTIF(S29:S30,"May") -> 0 | M10: =SUMIF(S34:S35,"May",N34:N35)+SUMIF(S34:S35,"May",H34:H35) -> 0 | N10: =(SUMIF(S34:S35,"May",L34:L35))-((SUMIF(S34:S35,"May",P34:P35)+SUMIF(S34:S35,"May",O34:O35))) -> 0 | O10: =SUMIF(S34:S35,"May",Q34:Q35) -> 0 | Q10: =COUNTIF(S34:S35,"May") -> 0 | R10: =SUMIF(S39:S40,"May",N39:N40)+SUMIF(S39:S40,"May",H39:H40) -> 0 | S10: =(SUMIF(S39:S40,"May",L39:L40))-((SUMIF(S39:S40,"May",P39:P40)+SUMIF(S39:S40,"May",O39:O40))) -> 0 | T10: =SUMIF(S39:S40,"May",Q39:Q40) -> 0 | V10: =COUNTIF(S39:S40,"May") -> 0
